2022-09-09 03:16:26,364 INFO    StreamThr :35553 [internal.py:wandb_internal():90] W&B internal server running at pid: 35553, started at: 2022-09-09 03:16:26.364537
2022-09-09 03:16:26,365 DEBUG   HandlerThread:35553 [handler.py:handle_request():141] handle_request: status
2022-09-09 03:16:26,367 DEBUG   SenderThread:35553 [sender.py:send_request():316] send_request: status
2022-09-09 03:16:26,367 DEBUG   SenderThread:35553 [sender.py:send():302] send: header
2022-09-09 03:16:26,367 DEBUG   SenderThread:35553 [sender.py:send():302] send: run
2022-09-09 03:16:26,368 INFO    WriterThread:35553 [datastore.py:open_for_write():75] open: /home/frozenwolf/Desktop/neurIPS/Hecker_rl/wandb/run-20220909_031626-1qrjcf6j/run-1qrjcf6j.wandb
2022-09-09 03:16:27,280 ERROR   SenderThread:35553 [internal_api.py:execute():207] 404 response executing GraphQL.
2022-09-09 03:16:27,280 ERROR   SenderThread:35553 [internal_api.py:execute():208] {"errors":[{"message":"project not found","path":["upsertBucket"]}],"data":{"upsertBucket":null}}
2022-09-09 03:16:27,368 INFO    HandlerThread:35553 [handler.py:finish():810] shutting down handler
2022-09-09 03:16:27,369 INFO    WriterThread:35553 [datastore.py:close():279] close: /home/frozenwolf/Desktop/neurIPS/Hecker_rl/wandb/run-20220909_031626-1qrjcf6j/run-1qrjcf6j.wandb
2022-09-09 03:16:27,369 ERROR   StreamThr :35553 [internal.py:wandb_internal():165] Thread SenderThread:
Traceback (most recent call last):
  File "/home/frozenwolf/miniconda3/envs/citylearn/lib/python3.10/site-packages/wandb/sdk/lib/retry.py", line 113, in __call__
    result = self._call_fn(*args, **kwargs)
  File "/home/frozenwolf/miniconda3/envs/citylearn/lib/python3.10/site-packages/wandb/sdk/internal/internal_api.py", line 204, in execute
    return self.client.execute(*args, **kwargs)  # type: ignore
  File "/home/frozenwolf/miniconda3/envs/citylearn/lib/python3.10/site-packages/wandb/vendor/gql-0.2.0/wandb_gql/client.py", line 52, in execute
    result = self._get_result(document, *args, **kwargs)
  File "/home/frozenwolf/miniconda3/envs/citylearn/lib/python3.10/site-packages/wandb/vendor/gql-0.2.0/wandb_gql/client.py", line 60, in _get_result
    return self.transport.execute(document, *args, **kwargs)
  File "/home/frozenwolf/miniconda3/envs/citylearn/lib/python3.10/site-packages/wandb/vendor/gql-0.2.0/wandb_gql/transport/requests.py", line 39, in execute
    request.raise_for_status()
  File "/home/frozenwolf/miniconda3/envs/citylearn/lib/python3.10/site-packages/requests/models.py", line 960, in raise_for_status
    raise HTTPError(http_error_msg, response=self)
requests.exceptions.HTTPError: 404 Client Error: Not Found for url: https://api.wandb.ai/graphql

During handling of the above exception, another exception occurred:

Traceback (most recent call last):
  File "/home/frozenwolf/miniconda3/envs/citylearn/lib/python3.10/site-packages/wandb/apis/normalize.py", line 25, in wrapper
    return func(*args, **kwargs)
  File "/home/frozenwolf/miniconda3/envs/citylearn/lib/python3.10/site-packages/wandb/sdk/internal/internal_api.py", line 1465, in upsert_run
    response = self.gql(
  File "/home/frozenwolf/miniconda3/envs/citylearn/lib/python3.10/site-packages/wandb/sdk/lib/retry.py", line 129, in __call__
    retry_timedelta_triggered = check_retry_fn(e)
  File "/home/frozenwolf/miniconda3/envs/citylearn/lib/python3.10/site-packages/wandb/util.py", line 942, in check_retry_fn
    return fallback_retry_fn(e)
  File "/home/frozenwolf/miniconda3/envs/citylearn/lib/python3.10/site-packages/wandb/util.py", line 889, in no_retry_auth
    raise CommError("Permission denied, ask the project owner to grant you access")
wandb.errors.CommError: Permission denied, ask the project owner to grant you access

During handling of the above exception, another exception occurred:

Traceback (most recent call last):
  File "/home/frozenwolf/miniconda3/envs/citylearn/lib/python3.10/site-packages/wandb/sdk/internal/internal_util.py", line 51, in run
    self._run()
  File "/home/frozenwolf/miniconda3/envs/citylearn/lib/python3.10/site-packages/wandb/sdk/internal/internal_util.py", line 102, in _run
    self._process(record)
  File "/home/frozenwolf/miniconda3/envs/citylearn/lib/python3.10/site-packages/wandb/sdk/internal/internal.py", line 310, in _process
    self._sm.send(record)
  File "/home/frozenwolf/miniconda3/envs/citylearn/lib/python3.10/site-packages/wandb/sdk/internal/sender.py", line 304, in send
    send_handler(record)
  File "/home/frozenwolf/miniconda3/envs/citylearn/lib/python3.10/site-packages/wandb/sdk/internal/sender.py", line 782, in send_run
    self._init_run(run, config_value_dict)
  File "/home/frozenwolf/miniconda3/envs/citylearn/lib/python3.10/site-packages/wandb/sdk/internal/sender.py", line 808, in _init_run
    server_run, inserted, server_messages = self._api.upsert_run(
  File "/home/frozenwolf/miniconda3/envs/citylearn/lib/python3.10/site-packages/wandb/apis/normalize.py", line 61, in wrapper
    raise CommError(message, err).with_traceback(sys.exc_info()[2])
  File "/home/frozenwolf/miniconda3/envs/citylearn/lib/python3.10/site-packages/wandb/apis/normalize.py", line 25, in wrapper
    return func(*args, **kwargs)
  File "/home/frozenwolf/miniconda3/envs/citylearn/lib/python3.10/site-packages/wandb/sdk/internal/internal_api.py", line 1465, in upsert_run
    response = self.gql(
  File "/home/frozenwolf/miniconda3/envs/citylearn/lib/python3.10/site-packages/wandb/sdk/lib/retry.py", line 129, in __call__
    retry_timedelta_triggered = check_retry_fn(e)
  File "/home/frozenwolf/miniconda3/envs/citylearn/lib/python3.10/site-packages/wandb/util.py", line 942, in check_retry_fn
    return fallback_retry_fn(e)
  File "/home/frozenwolf/miniconda3/envs/citylearn/lib/python3.10/site-packages/wandb/util.py", line 889, in no_retry_auth
    raise CommError("Permission denied, ask the project owner to grant you access")
wandb.errors.CommError: Permission denied, ask the project owner to grant you access
