2022-09-04 11:10:51 INFO Running runs: []
2022-09-04 11:10:52 INFO Agent received command: run
2022-09-04 11:10:52 INFO Agent starting run with config:
	actor_lr: 0.0001
	algo: ddpg
	batch_size: 256
	critic_lr: 0.0001
	device: cuda
	epochs: 1000
	gamma: 0.99
	tau: 0.01
2022-09-04 11:10:52 INFO About to run command: /usr/bin/env python citylearn-2022-starter-kit/train.py --actor_lr=0.0001 --algo=ddpg --batch_size=256 --critic_lr=0.0001 --device=cuda --epochs=1000 --gamma=0.99 --tau=0.01
2022-09-04 11:10:57 INFO Running runs: ['1xr57jrl']
2022-09-04 11:10:57 INFO Cleaning up finished run: 1xr57jrl
2022-09-04 11:10:58 INFO Agent received command: run
2022-09-04 11:10:58 INFO Agent starting run with config:
	actor_lr: 0.0001
	algo: ddpg
	batch_size: 256
	critic_lr: 0.0001
	device: cuda
	epochs: 1000
	gamma: 0.99
	tau: 0.02
2022-09-04 11:10:58 INFO About to run command: /usr/bin/env python citylearn-2022-starter-kit/train.py --actor_lr=0.0001 --algo=ddpg --batch_size=256 --critic_lr=0.0001 --device=cuda --epochs=1000 --gamma=0.99 --tau=0.02
2022-09-04 11:11:44 INFO Running runs: []
2022-09-04 11:11:45 INFO Agent received command: run
2022-09-04 11:11:45 INFO Agent starting run with config:
	actor_lr: 0.0001
	algo: ddpg
	batch_size: 256
	critic_lr: 0.0001
	device: cuda
	epochs: 1000
	gamma: 0.99
	tau: 0.03
2022-09-04 11:11:45 INFO About to run command: /usr/bin/env python citylearn-2022-starter-kit/train.py --actor_lr=0.0001 --algo=ddpg --batch_size=256 --critic_lr=0.0001 --device=cuda --epochs=1000 --gamma=0.99 --tau=0.03
2022-09-04 11:11:50 INFO Running runs: ['m70f8994']
2022-09-04 11:49:52 INFO Cleaning up finished run: m70f8994
2022-09-04 11:51:09 INFO Agent received command: run
2022-09-04 11:51:09 INFO Agent starting run with config:
	actor_lr: 0.0001
	algo: ddpg
	batch_size: 256
	critic_lr: 0.0001
	device: cuda
	epochs: 1000
	gamma: 0.99
	tau: 0.04
2022-09-04 11:51:09 INFO About to run command: /usr/bin/env python citylearn-2022-starter-kit/train.py --actor_lr=0.0001 --algo=ddpg --batch_size=256 --critic_lr=0.0001 --device=cuda --epochs=1000 --gamma=0.99 --tau=0.04
2022-09-04 11:51:14 INFO Running runs: ['7e80ghfp']
2022-09-04 11:55:26 ERROR Retry attempt failed:
Traceback (most recent call last):
  File "/home/frozenwolf/miniconda3/envs/citylearn/lib/python3.10/site-packages/urllib3/connection.py", line 174, in _new_conn
    conn = connection.create_connection(
  File "/home/frozenwolf/miniconda3/envs/citylearn/lib/python3.10/site-packages/urllib3/util/connection.py", line 72, in create_connection
    for res in socket.getaddrinfo(host, port, family, socket.SOCK_STREAM):
  File "/home/frozenwolf/miniconda3/envs/citylearn/lib/python3.10/socket.py", line 955, in getaddrinfo
    for res in _socket.getaddrinfo(host, port, family, type, proto, flags):
socket.gaierror: [Errno -3] Temporary failure in name resolution

During handling of the above exception, another exception occurred:

Traceback (most recent call last):
  File "/home/frozenwolf/miniconda3/envs/citylearn/lib/python3.10/site-packages/urllib3/connectionpool.py", line 703, in urlopen
    httplib_response = self._make_request(
  File "/home/frozenwolf/miniconda3/envs/citylearn/lib/python3.10/site-packages/urllib3/connectionpool.py", line 386, in _make_request
    self._validate_conn(conn)
  File "/home/frozenwolf/miniconda3/envs/citylearn/lib/python3.10/site-packages/urllib3/connectionpool.py", line 1040, in _validate_conn
    conn.connect()
  File "/home/frozenwolf/miniconda3/envs/citylearn/lib/python3.10/site-packages/urllib3/connection.py", line 358, in connect
    self.sock = conn = self._new_conn()
  File "/home/frozenwolf/miniconda3/envs/citylearn/lib/python3.10/site-packages/urllib3/connection.py", line 186, in _new_conn
    raise NewConnectionError(
urllib3.exceptions.NewConnectionError: <urllib3.connection.HTTPSConnection object at 0x7fc3a92127a0>: Failed to establish a new connection: [Errno -3] Temporary failure in name resolution

During handling of the above exception, another exception occurred:

Traceback (most recent call last):
  File "/home/frozenwolf/miniconda3/envs/citylearn/lib/python3.10/site-packages/requests/adapters.py", line 440, in send
    resp = conn.urlopen(
  File "/home/frozenwolf/miniconda3/envs/citylearn/lib/python3.10/site-packages/urllib3/connectionpool.py", line 785, in urlopen
    retries = retries.increment(
  File "/home/frozenwolf/miniconda3/envs/citylearn/lib/python3.10/site-packages/urllib3/util/retry.py", line 592, in increment
    raise MaxRetryError(_pool, url, error or ResponseError(cause))
urllib3.exceptions.MaxRetryError: HTTPSConnectionPool(host='api.wandb.ai', port=443): Max retries exceeded with url: /graphql (Caused by NewConnectionError('<urllib3.connection.HTTPSConnection object at 0x7fc3a92127a0>: Failed to establish a new connection: [Errno -3] Temporary failure in name resolution'))

During handling of the above exception, another exception occurred:

Traceback (most recent call last):
  File "/home/frozenwolf/miniconda3/envs/citylearn/lib/python3.10/site-packages/wandb/sdk/lib/retry.py", line 113, in __call__
    result = self._call_fn(*args, **kwargs)
  File "/home/frozenwolf/miniconda3/envs/citylearn/lib/python3.10/site-packages/wandb/sdk/internal/internal_api.py", line 204, in execute
    return self.client.execute(*args, **kwargs)  # type: ignore
  File "/home/frozenwolf/miniconda3/envs/citylearn/lib/python3.10/site-packages/wandb/vendor/gql-0.2.0/wandb_gql/client.py", line 52, in execute
    result = self._get_result(document, *args, **kwargs)
  File "/home/frozenwolf/miniconda3/envs/citylearn/lib/python3.10/site-packages/wandb/vendor/gql-0.2.0/wandb_gql/client.py", line 60, in _get_result
    return self.transport.execute(document, *args, **kwargs)
  File "/home/frozenwolf/miniconda3/envs/citylearn/lib/python3.10/site-packages/wandb/vendor/gql-0.2.0/wandb_gql/transport/requests.py", line 38, in execute
    request = requests.post(self.url, **post_args)
  File "/home/frozenwolf/miniconda3/envs/citylearn/lib/python3.10/site-packages/requests/api.py", line 117, in post
    return request('post', url, data=data, json=json, **kwargs)
  File "/home/frozenwolf/miniconda3/envs/citylearn/lib/python3.10/site-packages/requests/api.py", line 61, in request
    return session.request(method=method, url=url, **kwargs)
  File "/home/frozenwolf/miniconda3/envs/citylearn/lib/python3.10/site-packages/requests/sessions.py", line 529, in request
    resp = self.send(prep, **send_kwargs)
  File "/home/frozenwolf/miniconda3/envs/citylearn/lib/python3.10/site-packages/requests/sessions.py", line 645, in send
    r = adapter.send(request, **kwargs)
  File "/home/frozenwolf/miniconda3/envs/citylearn/lib/python3.10/site-packages/requests/adapters.py", line 519, in send
    raise ConnectionError(e, request=request)
requests.exceptions.ConnectionError: HTTPSConnectionPool(host='api.wandb.ai', port=443): Max retries exceeded with url: /graphql (Caused by NewConnectionError('<urllib3.connection.HTTPSConnection object at 0x7fc3a92127a0>: Failed to establish a new connection: [Errno -3] Temporary failure in name resolution'))
2022-09-04 14:24:20 ERROR dropped chunk HTTPSConnectionPool(host='api.wandb.ai', port=443): Max retries exceeded with url: /files/cleancity_challenge_rl/CITYCLEAN_RL/7e80ghfp/file_stream (Caused by NewConnectionError('<urllib3.connection.HTTPSConnection object at 0x7f79a46833a0>: Failed to establish a new connection: [Errno -3] Temporary failure in name resolution'))
NoneType: None
2022-09-04 15:33:13 INFO Cleaning up finished run: 7e80ghfp
2022-09-04 15:33:14 INFO Agent received command: run
2022-09-04 15:33:14 INFO Agent starting run with config:
	actor_lr: 0.0001
	algo: ddpg
	batch_size: 256
	critic_lr: 0.0001
	device: cuda
	epochs: 1000
	gamma: 0.99
	tau: 0.01
2022-09-04 15:33:14 INFO About to run command: /usr/bin/env python citylearn-2022-starter-kit/train.py --actor_lr=0.0001 --algo=ddpg --batch_size=256 --critic_lr=0.0001 --device=cuda --epochs=1000 --gamma=0.99 --tau=0.01
2022-09-04 15:33:19 INFO Running runs: ['1xr57jrl']
2022-09-04 16:02:06 ERROR Retry attempt failed:
Traceback (most recent call last):
  File "/home/frozenwolf/miniconda3/envs/citylearn/lib/python3.10/site-packages/urllib3/connection.py", line 174, in _new_conn
    conn = connection.create_connection(
  File "/home/frozenwolf/miniconda3/envs/citylearn/lib/python3.10/site-packages/urllib3/util/connection.py", line 72, in create_connection
    for res in socket.getaddrinfo(host, port, family, socket.SOCK_STREAM):
  File "/home/frozenwolf/miniconda3/envs/citylearn/lib/python3.10/socket.py", line 955, in getaddrinfo
    for res in _socket.getaddrinfo(host, port, family, type, proto, flags):
socket.gaierror: [Errno -3] Temporary failure in name resolution

During handling of the above exception, another exception occurred:

Traceback (most recent call last):
  File "/home/frozenwolf/miniconda3/envs/citylearn/lib/python3.10/site-packages/urllib3/connectionpool.py", line 703, in urlopen
    httplib_response = self._make_request(
  File "/home/frozenwolf/miniconda3/envs/citylearn/lib/python3.10/site-packages/urllib3/connectionpool.py", line 386, in _make_request
    self._validate_conn(conn)
  File "/home/frozenwolf/miniconda3/envs/citylearn/lib/python3.10/site-packages/urllib3/connectionpool.py", line 1040, in _validate_conn
    conn.connect()
  File "/home/frozenwolf/miniconda3/envs/citylearn/lib/python3.10/site-packages/urllib3/connection.py", line 358, in connect
    self.sock = conn = self._new_conn()
  File "/home/frozenwolf/miniconda3/envs/citylearn/lib/python3.10/site-packages/urllib3/connection.py", line 186, in _new_conn
    raise NewConnectionError(
urllib3.exceptions.NewConnectionError: <urllib3.connection.HTTPSConnection object at 0x7fc3a9201b70>: Failed to establish a new connection: [Errno -3] Temporary failure in name resolution

During handling of the above exception, another exception occurred:

Traceback (most recent call last):
  File "/home/frozenwolf/miniconda3/envs/citylearn/lib/python3.10/site-packages/requests/adapters.py", line 440, in send
    resp = conn.urlopen(
  File "/home/frozenwolf/miniconda3/envs/citylearn/lib/python3.10/site-packages/urllib3/connectionpool.py", line 785, in urlopen
    retries = retries.increment(
  File "/home/frozenwolf/miniconda3/envs/citylearn/lib/python3.10/site-packages/urllib3/util/retry.py", line 592, in increment
    raise MaxRetryError(_pool, url, error or ResponseError(cause))
urllib3.exceptions.MaxRetryError: HTTPSConnectionPool(host='api.wandb.ai', port=443): Max retries exceeded with url: /graphql (Caused by NewConnectionError('<urllib3.connection.HTTPSConnection object at 0x7fc3a9201b70>: Failed to establish a new connection: [Errno -3] Temporary failure in name resolution'))

During handling of the above exception, another exception occurred:

Traceback (most recent call last):
  File "/home/frozenwolf/miniconda3/envs/citylearn/lib/python3.10/site-packages/wandb/sdk/lib/retry.py", line 113, in __call__
    result = self._call_fn(*args, **kwargs)
  File "/home/frozenwolf/miniconda3/envs/citylearn/lib/python3.10/site-packages/wandb/sdk/internal/internal_api.py", line 204, in execute
    return self.client.execute(*args, **kwargs)  # type: ignore
  File "/home/frozenwolf/miniconda3/envs/citylearn/lib/python3.10/site-packages/wandb/vendor/gql-0.2.0/wandb_gql/client.py", line 52, in execute
    result = self._get_result(document, *args, **kwargs)
  File "/home/frozenwolf/miniconda3/envs/citylearn/lib/python3.10/site-packages/wandb/vendor/gql-0.2.0/wandb_gql/client.py", line 60, in _get_result
    return self.transport.execute(document, *args, **kwargs)
  File "/home/frozenwolf/miniconda3/envs/citylearn/lib/python3.10/site-packages/wandb/vendor/gql-0.2.0/wandb_gql/transport/requests.py", line 38, in execute
    request = requests.post(self.url, **post_args)
  File "/home/frozenwolf/miniconda3/envs/citylearn/lib/python3.10/site-packages/requests/api.py", line 117, in post
    return request('post', url, data=data, json=json, **kwargs)
  File "/home/frozenwolf/miniconda3/envs/citylearn/lib/python3.10/site-packages/requests/api.py", line 61, in request
    return session.request(method=method, url=url, **kwargs)
  File "/home/frozenwolf/miniconda3/envs/citylearn/lib/python3.10/site-packages/requests/sessions.py", line 529, in request
    resp = self.send(prep, **send_kwargs)
  File "/home/frozenwolf/miniconda3/envs/citylearn/lib/python3.10/site-packages/requests/sessions.py", line 645, in send
    r = adapter.send(request, **kwargs)
  File "/home/frozenwolf/miniconda3/envs/citylearn/lib/python3.10/site-packages/requests/adapters.py", line 519, in send
    raise ConnectionError(e, request=request)
requests.exceptions.ConnectionError: HTTPSConnectionPool(host='api.wandb.ai', port=443): Max retries exceeded with url: /graphql (Caused by NewConnectionError('<urllib3.connection.HTTPSConnection object at 0x7fc3a9201b70>: Failed to establish a new connection: [Errno -3] Temporary failure in name resolution'))
2022-09-04 16:11:12 INFO Cleaning up finished run: 1xr57jrl
2022-09-04 16:11:13 INFO Agent received command: run
2022-09-04 16:11:13 INFO Agent starting run with config:
	actor_lr: 0.0001
	algo: ddpg
	batch_size: 256
	critic_lr: 0.0001
	device: cuda
	epochs: 1000
	gamma: 0.99
	tau: 0.02
2022-09-04 16:11:13 INFO About to run command: /usr/bin/env python citylearn-2022-starter-kit/train.py --actor_lr=0.0001 --algo=ddpg --batch_size=256 --critic_lr=0.0001 --device=cuda --epochs=1000 --gamma=0.99 --tau=0.02
2022-09-04 16:11:18 INFO Running runs: ['pd1z0y5b']
2022-09-04 16:52:27 INFO Cleaning up finished run: pd1z0y5b
2022-09-04 16:52:29 INFO Agent received command: run
2022-09-04 16:52:29 INFO Agent starting run with config:
	actor_lr: 0.0001
	algo: ddpg
	batch_size: 256
	critic_lr: 0.0001
	device: cuda
	epochs: 1000
	gamma: 0.99
	tau: 0.05
2022-09-04 16:52:29 INFO About to run command: /usr/bin/env python citylearn-2022-starter-kit/train.py --actor_lr=0.0001 --algo=ddpg --batch_size=256 --critic_lr=0.0001 --device=cuda --epochs=1000 --gamma=0.99 --tau=0.05
2022-09-04 16:52:34 INFO Running runs: ['ipm4um94']
2022-09-04 17:02:32 ERROR Retry attempt failed:
Traceback (most recent call last):
  File "/home/frozenwolf/miniconda3/envs/citylearn/lib/python3.10/site-packages/urllib3/connection.py", line 174, in _new_conn
    conn = connection.create_connection(
  File "/home/frozenwolf/miniconda3/envs/citylearn/lib/python3.10/site-packages/urllib3/util/connection.py", line 95, in create_connection
    raise err
  File "/home/frozenwolf/miniconda3/envs/citylearn/lib/python3.10/site-packages/urllib3/util/connection.py", line 85, in create_connection
    sock.connect(sa)
OSError: [Errno 113] No route to host

During handling of the above exception, another exception occurred:

Traceback (most recent call last):
  File "/home/frozenwolf/miniconda3/envs/citylearn/lib/python3.10/site-packages/urllib3/connectionpool.py", line 703, in urlopen
    httplib_response = self._make_request(
  File "/home/frozenwolf/miniconda3/envs/citylearn/lib/python3.10/site-packages/urllib3/connectionpool.py", line 386, in _make_request
    self._validate_conn(conn)
  File "/home/frozenwolf/miniconda3/envs/citylearn/lib/python3.10/site-packages/urllib3/connectionpool.py", line 1040, in _validate_conn
    conn.connect()
  File "/home/frozenwolf/miniconda3/envs/citylearn/lib/python3.10/site-packages/urllib3/connection.py", line 358, in connect
    self.sock = conn = self._new_conn()
  File "/home/frozenwolf/miniconda3/envs/citylearn/lib/python3.10/site-packages/urllib3/connection.py", line 186, in _new_conn
    raise NewConnectionError(
urllib3.exceptions.NewConnectionError: <urllib3.connection.HTTPSConnection object at 0x7fc3a9201210>: Failed to establish a new connection: [Errno 113] No route to host

During handling of the above exception, another exception occurred:

Traceback (most recent call last):
  File "/home/frozenwolf/miniconda3/envs/citylearn/lib/python3.10/site-packages/requests/adapters.py", line 440, in send
    resp = conn.urlopen(
  File "/home/frozenwolf/miniconda3/envs/citylearn/lib/python3.10/site-packages/urllib3/connectionpool.py", line 785, in urlopen
    retries = retries.increment(
  File "/home/frozenwolf/miniconda3/envs/citylearn/lib/python3.10/site-packages/urllib3/util/retry.py", line 592, in increment
    raise MaxRetryError(_pool, url, error or ResponseError(cause))
urllib3.exceptions.MaxRetryError: HTTPSConnectionPool(host='api.wandb.ai', port=443): Max retries exceeded with url: /graphql (Caused by NewConnectionError('<urllib3.connection.HTTPSConnection object at 0x7fc3a9201210>: Failed to establish a new connection: [Errno 113] No route to host'))

During handling of the above exception, another exception occurred:

Traceback (most recent call last):
  File "/home/frozenwolf/miniconda3/envs/citylearn/lib/python3.10/site-packages/wandb/sdk/lib/retry.py", line 113, in __call__
    result = self._call_fn(*args, **kwargs)
  File "/home/frozenwolf/miniconda3/envs/citylearn/lib/python3.10/site-packages/wandb/sdk/internal/internal_api.py", line 204, in execute
    return self.client.execute(*args, **kwargs)  # type: ignore
  File "/home/frozenwolf/miniconda3/envs/citylearn/lib/python3.10/site-packages/wandb/vendor/gql-0.2.0/wandb_gql/client.py", line 52, in execute
    result = self._get_result(document, *args, **kwargs)
  File "/home/frozenwolf/miniconda3/envs/citylearn/lib/python3.10/site-packages/wandb/vendor/gql-0.2.0/wandb_gql/client.py", line 60, in _get_result
    return self.transport.execute(document, *args, **kwargs)
  File "/home/frozenwolf/miniconda3/envs/citylearn/lib/python3.10/site-packages/wandb/vendor/gql-0.2.0/wandb_gql/transport/requests.py", line 38, in execute
    request = requests.post(self.url, **post_args)
  File "/home/frozenwolf/miniconda3/envs/citylearn/lib/python3.10/site-packages/requests/api.py", line 117, in post
    return request('post', url, data=data, json=json, **kwargs)
  File "/home/frozenwolf/miniconda3/envs/citylearn/lib/python3.10/site-packages/requests/api.py", line 61, in request
    return session.request(method=method, url=url, **kwargs)
  File "/home/frozenwolf/miniconda3/envs/citylearn/lib/python3.10/site-packages/requests/sessions.py", line 529, in request
    resp = self.send(prep, **send_kwargs)
  File "/home/frozenwolf/miniconda3/envs/citylearn/lib/python3.10/site-packages/requests/sessions.py", line 645, in send
    r = adapter.send(request, **kwargs)
  File "/home/frozenwolf/miniconda3/envs/citylearn/lib/python3.10/site-packages/requests/adapters.py", line 519, in send
    raise ConnectionError(e, request=request)
requests.exceptions.ConnectionError: HTTPSConnectionPool(host='api.wandb.ai', port=443): Max retries exceeded with url: /graphql (Caused by NewConnectionError('<urllib3.connection.HTTPSConnection object at 0x7fc3a9201210>: Failed to establish a new connection: [Errno 113] No route to host'))
2022-09-04 17:24:50 ERROR Retry attempt failed:
Traceback (most recent call last):
  File "/home/frozenwolf/miniconda3/envs/citylearn/lib/python3.10/site-packages/urllib3/connection.py", line 174, in _new_conn
    conn = connection.create_connection(
  File "/home/frozenwolf/miniconda3/envs/citylearn/lib/python3.10/site-packages/urllib3/util/connection.py", line 72, in create_connection
    for res in socket.getaddrinfo(host, port, family, socket.SOCK_STREAM):
  File "/home/frozenwolf/miniconda3/envs/citylearn/lib/python3.10/socket.py", line 955, in getaddrinfo
    for res in _socket.getaddrinfo(host, port, family, type, proto, flags):
socket.gaierror: [Errno -3] Temporary failure in name resolution

During handling of the above exception, another exception occurred:

Traceback (most recent call last):
  File "/home/frozenwolf/miniconda3/envs/citylearn/lib/python3.10/site-packages/urllib3/connectionpool.py", line 703, in urlopen
    httplib_response = self._make_request(
  File "/home/frozenwolf/miniconda3/envs/citylearn/lib/python3.10/site-packages/urllib3/connectionpool.py", line 386, in _make_request
    self._validate_conn(conn)
  File "/home/frozenwolf/miniconda3/envs/citylearn/lib/python3.10/site-packages/urllib3/connectionpool.py", line 1040, in _validate_conn
    conn.connect()
  File "/home/frozenwolf/miniconda3/envs/citylearn/lib/python3.10/site-packages/urllib3/connection.py", line 358, in connect
    self.sock = conn = self._new_conn()
  File "/home/frozenwolf/miniconda3/envs/citylearn/lib/python3.10/site-packages/urllib3/connection.py", line 186, in _new_conn
    raise NewConnectionError(
urllib3.exceptions.NewConnectionError: <urllib3.connection.HTTPSConnection object at 0x7fc3a9213c40>: Failed to establish a new connection: [Errno -3] Temporary failure in name resolution

During handling of the above exception, another exception occurred:

Traceback (most recent call last):
  File "/home/frozenwolf/miniconda3/envs/citylearn/lib/python3.10/site-packages/requests/adapters.py", line 440, in send
    resp = conn.urlopen(
  File "/home/frozenwolf/miniconda3/envs/citylearn/lib/python3.10/site-packages/urllib3/connectionpool.py", line 785, in urlopen
    retries = retries.increment(
  File "/home/frozenwolf/miniconda3/envs/citylearn/lib/python3.10/site-packages/urllib3/util/retry.py", line 592, in increment
    raise MaxRetryError(_pool, url, error or ResponseError(cause))
urllib3.exceptions.MaxRetryError: HTTPSConnectionPool(host='api.wandb.ai', port=443): Max retries exceeded with url: /graphql (Caused by NewConnectionError('<urllib3.connection.HTTPSConnection object at 0x7fc3a9213c40>: Failed to establish a new connection: [Errno -3] Temporary failure in name resolution'))

During handling of the above exception, another exception occurred:

Traceback (most recent call last):
  File "/home/frozenwolf/miniconda3/envs/citylearn/lib/python3.10/site-packages/wandb/sdk/lib/retry.py", line 113, in __call__
    result = self._call_fn(*args, **kwargs)
  File "/home/frozenwolf/miniconda3/envs/citylearn/lib/python3.10/site-packages/wandb/sdk/internal/internal_api.py", line 204, in execute
    return self.client.execute(*args, **kwargs)  # type: ignore
  File "/home/frozenwolf/miniconda3/envs/citylearn/lib/python3.10/site-packages/wandb/vendor/gql-0.2.0/wandb_gql/client.py", line 52, in execute
    result = self._get_result(document, *args, **kwargs)
  File "/home/frozenwolf/miniconda3/envs/citylearn/lib/python3.10/site-packages/wandb/vendor/gql-0.2.0/wandb_gql/client.py", line 60, in _get_result
    return self.transport.execute(document, *args, **kwargs)
  File "/home/frozenwolf/miniconda3/envs/citylearn/lib/python3.10/site-packages/wandb/vendor/gql-0.2.0/wandb_gql/transport/requests.py", line 38, in execute
    request = requests.post(self.url, **post_args)
  File "/home/frozenwolf/miniconda3/envs/citylearn/lib/python3.10/site-packages/requests/api.py", line 117, in post
    return request('post', url, data=data, json=json, **kwargs)
  File "/home/frozenwolf/miniconda3/envs/citylearn/lib/python3.10/site-packages/requests/api.py", line 61, in request
    return session.request(method=method, url=url, **kwargs)
  File "/home/frozenwolf/miniconda3/envs/citylearn/lib/python3.10/site-packages/requests/sessions.py", line 529, in request
    resp = self.send(prep, **send_kwargs)
  File "/home/frozenwolf/miniconda3/envs/citylearn/lib/python3.10/site-packages/requests/sessions.py", line 645, in send
    r = adapter.send(request, **kwargs)
  File "/home/frozenwolf/miniconda3/envs/citylearn/lib/python3.10/site-packages/requests/adapters.py", line 519, in send
    raise ConnectionError(e, request=request)
requests.exceptions.ConnectionError: HTTPSConnectionPool(host='api.wandb.ai', port=443): Max retries exceeded with url: /graphql (Caused by NewConnectionError('<urllib3.connection.HTTPSConnection object at 0x7fc3a9213c40>: Failed to establish a new connection: [Errno -3] Temporary failure in name resolution'))
2022-09-04 17:29:44 INFO Cleaning up finished run: ipm4um94
2022-09-04 17:29:44 INFO Agent received command: run
2022-09-04 17:29:44 INFO Agent starting run with config:
	actor_lr: 0.0001
	algo: ddpg
	batch_size: 256
	critic_lr: 0.0002
	device: cuda
	epochs: 1000
	gamma: 0.99
	tau: 0.01
2022-09-04 17:29:44 INFO About to run command: /usr/bin/env python citylearn-2022-starter-kit/train.py --actor_lr=0.0001 --algo=ddpg --batch_size=256 --critic_lr=0.0002 --device=cuda --epochs=1000 --gamma=0.99 --tau=0.01
2022-09-04 17:29:49 INFO Running runs: ['7b04lj0j']
2022-09-04 18:06:16 INFO Cleaning up finished run: 7b04lj0j
2022-09-04 18:06:16 INFO Agent received command: run
2022-09-04 18:06:16 INFO Agent starting run with config:
	actor_lr: 0.0001
	algo: ddpg
	batch_size: 256
	critic_lr: 0.0002
	device: cuda
	epochs: 1000
	gamma: 0.99
	tau: 0.02
2022-09-04 18:06:16 INFO About to run command: /usr/bin/env python citylearn-2022-starter-kit/train.py --actor_lr=0.0001 --algo=ddpg --batch_size=256 --critic_lr=0.0002 --device=cuda --epochs=1000 --gamma=0.99 --tau=0.02
2022-09-04 18:06:21 INFO Running runs: ['ees8w57s']
2022-09-04 18:44:48 INFO Cleaning up finished run: ees8w57s
2022-09-04 18:44:49 INFO Agent received command: run
2022-09-04 18:44:49 INFO Agent starting run with config:
	actor_lr: 0.0001
	algo: ddpg
	batch_size: 256
	critic_lr: 0.0002
	device: cuda
	epochs: 1000
	gamma: 0.99
	tau: 0.03
2022-09-04 18:44:49 INFO About to run command: /usr/bin/env python citylearn-2022-starter-kit/train.py --actor_lr=0.0001 --algo=ddpg --batch_size=256 --critic_lr=0.0002 --device=cuda --epochs=1000 --gamma=0.99 --tau=0.03
2022-09-04 18:44:54 INFO Running runs: ['8x0mqx80']
2022-09-04 19:25:40 INFO Cleaning up finished run: 8x0mqx80
2022-09-04 19:26:09 INFO Agent received command: run
2022-09-04 19:26:09 INFO Agent starting run with config:
	actor_lr: 0.0001
	algo: ddpg
	batch_size: 256
	critic_lr: 0.0002
	device: cuda
	epochs: 1000
	gamma: 0.99
	tau: 0.04
2022-09-04 19:26:09 INFO About to run command: /usr/bin/env python citylearn-2022-starter-kit/train.py --actor_lr=0.0001 --algo=ddpg --batch_size=256 --critic_lr=0.0002 --device=cuda --epochs=1000 --gamma=0.99 --tau=0.04
2022-09-04 19:26:14 INFO Running runs: ['6tw0u28n']
2022-09-04 19:31:11 ERROR Retry attempt failed:
Traceback (most recent call last):
  File "/home/frozenwolf/miniconda3/envs/citylearn/lib/python3.10/site-packages/urllib3/connection.py", line 174, in _new_conn
    conn = connection.create_connection(
  File "/home/frozenwolf/miniconda3/envs/citylearn/lib/python3.10/site-packages/urllib3/util/connection.py", line 72, in create_connection
    for res in socket.getaddrinfo(host, port, family, socket.SOCK_STREAM):
  File "/home/frozenwolf/miniconda3/envs/citylearn/lib/python3.10/socket.py", line 955, in getaddrinfo
    for res in _socket.getaddrinfo(host, port, family, type, proto, flags):
socket.gaierror: [Errno -3] Temporary failure in name resolution

During handling of the above exception, another exception occurred:

Traceback (most recent call last):
  File "/home/frozenwolf/miniconda3/envs/citylearn/lib/python3.10/site-packages/urllib3/connectionpool.py", line 703, in urlopen
    httplib_response = self._make_request(
  File "/home/frozenwolf/miniconda3/envs/citylearn/lib/python3.10/site-packages/urllib3/connectionpool.py", line 386, in _make_request
    self._validate_conn(conn)
  File "/home/frozenwolf/miniconda3/envs/citylearn/lib/python3.10/site-packages/urllib3/connectionpool.py", line 1040, in _validate_conn
    conn.connect()
  File "/home/frozenwolf/miniconda3/envs/citylearn/lib/python3.10/site-packages/urllib3/connection.py", line 358, in connect
    self.sock = conn = self._new_conn()
  File "/home/frozenwolf/miniconda3/envs/citylearn/lib/python3.10/site-packages/urllib3/connection.py", line 186, in _new_conn
    raise NewConnectionError(
urllib3.exceptions.NewConnectionError: <urllib3.connection.HTTPSConnection object at 0x7fc3a9200430>: Failed to establish a new connection: [Errno -3] Temporary failure in name resolution

During handling of the above exception, another exception occurred:

Traceback (most recent call last):
  File "/home/frozenwolf/miniconda3/envs/citylearn/lib/python3.10/site-packages/requests/adapters.py", line 440, in send
    resp = conn.urlopen(
  File "/home/frozenwolf/miniconda3/envs/citylearn/lib/python3.10/site-packages/urllib3/connectionpool.py", line 785, in urlopen
    retries = retries.increment(
  File "/home/frozenwolf/miniconda3/envs/citylearn/lib/python3.10/site-packages/urllib3/util/retry.py", line 592, in increment
    raise MaxRetryError(_pool, url, error or ResponseError(cause))
urllib3.exceptions.MaxRetryError: HTTPSConnectionPool(host='api.wandb.ai', port=443): Max retries exceeded with url: /graphql (Caused by NewConnectionError('<urllib3.connection.HTTPSConnection object at 0x7fc3a9200430>: Failed to establish a new connection: [Errno -3] Temporary failure in name resolution'))

During handling of the above exception, another exception occurred:

Traceback (most recent call last):
  File "/home/frozenwolf/miniconda3/envs/citylearn/lib/python3.10/site-packages/wandb/sdk/lib/retry.py", line 113, in __call__
    result = self._call_fn(*args, **kwargs)
  File "/home/frozenwolf/miniconda3/envs/citylearn/lib/python3.10/site-packages/wandb/sdk/internal/internal_api.py", line 204, in execute
    return self.client.execute(*args, **kwargs)  # type: ignore
  File "/home/frozenwolf/miniconda3/envs/citylearn/lib/python3.10/site-packages/wandb/vendor/gql-0.2.0/wandb_gql/client.py", line 52, in execute
    result = self._get_result(document, *args, **kwargs)
  File "/home/frozenwolf/miniconda3/envs/citylearn/lib/python3.10/site-packages/wandb/vendor/gql-0.2.0/wandb_gql/client.py", line 60, in _get_result
    return self.transport.execute(document, *args, **kwargs)
  File "/home/frozenwolf/miniconda3/envs/citylearn/lib/python3.10/site-packages/wandb/vendor/gql-0.2.0/wandb_gql/transport/requests.py", line 38, in execute
    request = requests.post(self.url, **post_args)
  File "/home/frozenwolf/miniconda3/envs/citylearn/lib/python3.10/site-packages/requests/api.py", line 117, in post
    return request('post', url, data=data, json=json, **kwargs)
  File "/home/frozenwolf/miniconda3/envs/citylearn/lib/python3.10/site-packages/requests/api.py", line 61, in request
    return session.request(method=method, url=url, **kwargs)
  File "/home/frozenwolf/miniconda3/envs/citylearn/lib/python3.10/site-packages/requests/sessions.py", line 529, in request
    resp = self.send(prep, **send_kwargs)
  File "/home/frozenwolf/miniconda3/envs/citylearn/lib/python3.10/site-packages/requests/sessions.py", line 645, in send
    r = adapter.send(request, **kwargs)
  File "/home/frozenwolf/miniconda3/envs/citylearn/lib/python3.10/site-packages/requests/adapters.py", line 519, in send
    raise ConnectionError(e, request=request)
requests.exceptions.ConnectionError: HTTPSConnectionPool(host='api.wandb.ai', port=443): Max retries exceeded with url: /graphql (Caused by NewConnectionError('<urllib3.connection.HTTPSConnection object at 0x7fc3a9200430>: Failed to establish a new connection: [Errno -3] Temporary failure in name resolution'))
2022-09-04 20:06:46 ERROR Retry attempt failed:
Traceback (most recent call last):
  File "/home/frozenwolf/miniconda3/envs/citylearn/lib/python3.10/site-packages/urllib3/connection.py", line 174, in _new_conn
    conn = connection.create_connection(
  File "/home/frozenwolf/miniconda3/envs/citylearn/lib/python3.10/site-packages/urllib3/util/connection.py", line 72, in create_connection
    for res in socket.getaddrinfo(host, port, family, socket.SOCK_STREAM):
  File "/home/frozenwolf/miniconda3/envs/citylearn/lib/python3.10/socket.py", line 955, in getaddrinfo
    for res in _socket.getaddrinfo(host, port, family, type, proto, flags):
socket.gaierror: [Errno -3] Temporary failure in name resolution

During handling of the above exception, another exception occurred:

Traceback (most recent call last):
  File "/home/frozenwolf/miniconda3/envs/citylearn/lib/python3.10/site-packages/urllib3/connectionpool.py", line 703, in urlopen
    httplib_response = self._make_request(
  File "/home/frozenwolf/miniconda3/envs/citylearn/lib/python3.10/site-packages/urllib3/connectionpool.py", line 386, in _make_request
    self._validate_conn(conn)
  File "/home/frozenwolf/miniconda3/envs/citylearn/lib/python3.10/site-packages/urllib3/connectionpool.py", line 1040, in _validate_conn
    conn.connect()
  File "/home/frozenwolf/miniconda3/envs/citylearn/lib/python3.10/site-packages/urllib3/connection.py", line 358, in connect
    self.sock = conn = self._new_conn()
  File "/home/frozenwolf/miniconda3/envs/citylearn/lib/python3.10/site-packages/urllib3/connection.py", line 186, in _new_conn
    raise NewConnectionError(
urllib3.exceptions.NewConnectionError: <urllib3.connection.HTTPSConnection object at 0x7fc3a9201bd0>: Failed to establish a new connection: [Errno -3] Temporary failure in name resolution

During handling of the above exception, another exception occurred:

Traceback (most recent call last):
  File "/home/frozenwolf/miniconda3/envs/citylearn/lib/python3.10/site-packages/requests/adapters.py", line 440, in send
    resp = conn.urlopen(
  File "/home/frozenwolf/miniconda3/envs/citylearn/lib/python3.10/site-packages/urllib3/connectionpool.py", line 785, in urlopen
    retries = retries.increment(
  File "/home/frozenwolf/miniconda3/envs/citylearn/lib/python3.10/site-packages/urllib3/util/retry.py", line 592, in increment
    raise MaxRetryError(_pool, url, error or ResponseError(cause))
urllib3.exceptions.MaxRetryError: HTTPSConnectionPool(host='api.wandb.ai', port=443): Max retries exceeded with url: /graphql (Caused by NewConnectionError('<urllib3.connection.HTTPSConnection object at 0x7fc3a9201bd0>: Failed to establish a new connection: [Errno -3] Temporary failure in name resolution'))

During handling of the above exception, another exception occurred:

Traceback (most recent call last):
  File "/home/frozenwolf/miniconda3/envs/citylearn/lib/python3.10/site-packages/wandb/sdk/lib/retry.py", line 113, in __call__
    result = self._call_fn(*args, **kwargs)
  File "/home/frozenwolf/miniconda3/envs/citylearn/lib/python3.10/site-packages/wandb/sdk/internal/internal_api.py", line 204, in execute
    return self.client.execute(*args, **kwargs)  # type: ignore
  File "/home/frozenwolf/miniconda3/envs/citylearn/lib/python3.10/site-packages/wandb/vendor/gql-0.2.0/wandb_gql/client.py", line 52, in execute
    result = self._get_result(document, *args, **kwargs)
  File "/home/frozenwolf/miniconda3/envs/citylearn/lib/python3.10/site-packages/wandb/vendor/gql-0.2.0/wandb_gql/client.py", line 60, in _get_result
    return self.transport.execute(document, *args, **kwargs)
  File "/home/frozenwolf/miniconda3/envs/citylearn/lib/python3.10/site-packages/wandb/vendor/gql-0.2.0/wandb_gql/transport/requests.py", line 38, in execute
    request = requests.post(self.url, **post_args)
  File "/home/frozenwolf/miniconda3/envs/citylearn/lib/python3.10/site-packages/requests/api.py", line 117, in post
    return request('post', url, data=data, json=json, **kwargs)
  File "/home/frozenwolf/miniconda3/envs/citylearn/lib/python3.10/site-packages/requests/api.py", line 61, in request
    return session.request(method=method, url=url, **kwargs)
  File "/home/frozenwolf/miniconda3/envs/citylearn/lib/python3.10/site-packages/requests/sessions.py", line 529, in request
    resp = self.send(prep, **send_kwargs)
  File "/home/frozenwolf/miniconda3/envs/citylearn/lib/python3.10/site-packages/requests/sessions.py", line 645, in send
    r = adapter.send(request, **kwargs)
  File "/home/frozenwolf/miniconda3/envs/citylearn/lib/python3.10/site-packages/requests/adapters.py", line 519, in send
    raise ConnectionError(e, request=request)
requests.exceptions.ConnectionError: HTTPSConnectionPool(host='api.wandb.ai', port=443): Max retries exceeded with url: /graphql (Caused by NewConnectionError('<urllib3.connection.HTTPSConnection object at 0x7fc3a9201bd0>: Failed to establish a new connection: [Errno -3] Temporary failure in name resolution'))
2022-09-04 20:07:54 INFO Cleaning up finished run: 6tw0u28n
2022-09-04 20:07:55 INFO Agent received command: run
2022-09-04 20:07:55 INFO Agent starting run with config:
	actor_lr: 0.0001
	algo: ddpg
	batch_size: 256
	critic_lr: 0.0002
	device: cuda
	epochs: 1000
	gamma: 0.99
	tau: 0.05
2022-09-04 20:07:55 INFO About to run command: /usr/bin/env python citylearn-2022-starter-kit/train.py --actor_lr=0.0001 --algo=ddpg --batch_size=256 --critic_lr=0.0002 --device=cuda --epochs=1000 --gamma=0.99 --tau=0.05
2022-09-04 20:08:00 INFO Running runs: ['tsmxan4i']
2022-09-04 20:18:28 ERROR Retry attempt failed:
Traceback (most recent call last):
  File "/home/frozenwolf/miniconda3/envs/citylearn/lib/python3.10/site-packages/urllib3/connection.py", line 174, in _new_conn
    conn = connection.create_connection(
  File "/home/frozenwolf/miniconda3/envs/citylearn/lib/python3.10/site-packages/urllib3/util/connection.py", line 72, in create_connection
    for res in socket.getaddrinfo(host, port, family, socket.SOCK_STREAM):
  File "/home/frozenwolf/miniconda3/envs/citylearn/lib/python3.10/socket.py", line 955, in getaddrinfo
    for res in _socket.getaddrinfo(host, port, family, type, proto, flags):
socket.gaierror: [Errno -3] Temporary failure in name resolution

During handling of the above exception, another exception occurred:

Traceback (most recent call last):
  File "/home/frozenwolf/miniconda3/envs/citylearn/lib/python3.10/site-packages/urllib3/connectionpool.py", line 703, in urlopen
    httplib_response = self._make_request(
  File "/home/frozenwolf/miniconda3/envs/citylearn/lib/python3.10/site-packages/urllib3/connectionpool.py", line 386, in _make_request
    self._validate_conn(conn)
  File "/home/frozenwolf/miniconda3/envs/citylearn/lib/python3.10/site-packages/urllib3/connectionpool.py", line 1040, in _validate_conn
    conn.connect()
  File "/home/frozenwolf/miniconda3/envs/citylearn/lib/python3.10/site-packages/urllib3/connection.py", line 358, in connect
    self.sock = conn = self._new_conn()
  File "/home/frozenwolf/miniconda3/envs/citylearn/lib/python3.10/site-packages/urllib3/connection.py", line 186, in _new_conn
    raise NewConnectionError(
urllib3.exceptions.NewConnectionError: <urllib3.connection.HTTPSConnection object at 0x7fc3a9212650>: Failed to establish a new connection: [Errno -3] Temporary failure in name resolution

During handling of the above exception, another exception occurred:

Traceback (most recent call last):
  File "/home/frozenwolf/miniconda3/envs/citylearn/lib/python3.10/site-packages/requests/adapters.py", line 440, in send
    resp = conn.urlopen(
  File "/home/frozenwolf/miniconda3/envs/citylearn/lib/python3.10/site-packages/urllib3/connectionpool.py", line 785, in urlopen
    retries = retries.increment(
  File "/home/frozenwolf/miniconda3/envs/citylearn/lib/python3.10/site-packages/urllib3/util/retry.py", line 592, in increment
    raise MaxRetryError(_pool, url, error or ResponseError(cause))
urllib3.exceptions.MaxRetryError: HTTPSConnectionPool(host='api.wandb.ai', port=443): Max retries exceeded with url: /graphql (Caused by NewConnectionError('<urllib3.connection.HTTPSConnection object at 0x7fc3a9212650>: Failed to establish a new connection: [Errno -3] Temporary failure in name resolution'))

During handling of the above exception, another exception occurred:

Traceback (most recent call last):
  File "/home/frozenwolf/miniconda3/envs/citylearn/lib/python3.10/site-packages/wandb/sdk/lib/retry.py", line 113, in __call__
    result = self._call_fn(*args, **kwargs)
  File "/home/frozenwolf/miniconda3/envs/citylearn/lib/python3.10/site-packages/wandb/sdk/internal/internal_api.py", line 204, in execute
    return self.client.execute(*args, **kwargs)  # type: ignore
  File "/home/frozenwolf/miniconda3/envs/citylearn/lib/python3.10/site-packages/wandb/vendor/gql-0.2.0/wandb_gql/client.py", line 52, in execute
    result = self._get_result(document, *args, **kwargs)
  File "/home/frozenwolf/miniconda3/envs/citylearn/lib/python3.10/site-packages/wandb/vendor/gql-0.2.0/wandb_gql/client.py", line 60, in _get_result
    return self.transport.execute(document, *args, **kwargs)
  File "/home/frozenwolf/miniconda3/envs/citylearn/lib/python3.10/site-packages/wandb/vendor/gql-0.2.0/wandb_gql/transport/requests.py", line 38, in execute
    request = requests.post(self.url, **post_args)
  File "/home/frozenwolf/miniconda3/envs/citylearn/lib/python3.10/site-packages/requests/api.py", line 117, in post
    return request('post', url, data=data, json=json, **kwargs)
  File "/home/frozenwolf/miniconda3/envs/citylearn/lib/python3.10/site-packages/requests/api.py", line 61, in request
    return session.request(method=method, url=url, **kwargs)
  File "/home/frozenwolf/miniconda3/envs/citylearn/lib/python3.10/site-packages/requests/sessions.py", line 529, in request
    resp = self.send(prep, **send_kwargs)
  File "/home/frozenwolf/miniconda3/envs/citylearn/lib/python3.10/site-packages/requests/sessions.py", line 645, in send
    r = adapter.send(request, **kwargs)
  File "/home/frozenwolf/miniconda3/envs/citylearn/lib/python3.10/site-packages/requests/adapters.py", line 519, in send
    raise ConnectionError(e, request=request)
requests.exceptions.ConnectionError: HTTPSConnectionPool(host='api.wandb.ai', port=443): Max retries exceeded with url: /graphql (Caused by NewConnectionError('<urllib3.connection.HTTPSConnection object at 0x7fc3a9212650>: Failed to establish a new connection: [Errno -3] Temporary failure in name resolution'))
2022-09-04 20:44:16 INFO Cleaning up finished run: tsmxan4i
2022-09-04 20:44:17 INFO Agent received command: run
2022-09-04 20:44:17 INFO Agent starting run with config:
	actor_lr: 0.0001
	algo: ddpg
	batch_size: 256
	critic_lr: 0.0003
	device: cuda
	epochs: 1000
	gamma: 0.99
	tau: 0.01
2022-09-04 20:44:17 INFO About to run command: /usr/bin/env python citylearn-2022-starter-kit/train.py --actor_lr=0.0001 --algo=ddpg --batch_size=256 --critic_lr=0.0003 --device=cuda --epochs=1000 --gamma=0.99 --tau=0.01
2022-09-04 20:44:22 INFO Running runs: ['khprl3bb']
2022-09-04 21:26:45 INFO Cleaning up finished run: khprl3bb
2022-09-04 21:26:45 INFO Agent received command: run
2022-09-04 21:26:45 INFO Agent starting run with config:
	actor_lr: 0.0001
	algo: ddpg
	batch_size: 256
	critic_lr: 0.0003
	device: cuda
	epochs: 1000
	gamma: 0.99
	tau: 0.02
2022-09-04 21:26:45 INFO About to run command: /usr/bin/env python citylearn-2022-starter-kit/train.py --actor_lr=0.0001 --algo=ddpg --batch_size=256 --critic_lr=0.0003 --device=cuda --epochs=1000 --gamma=0.99 --tau=0.02
2022-09-04 21:26:50 INFO Running runs: ['ldf7sb3p']
2022-09-04 21:48:11 ERROR Retry attempt failed:
Traceback (most recent call last):
  File "/home/frozenwolf/miniconda3/envs/citylearn/lib/python3.10/site-packages/urllib3/connection.py", line 174, in _new_conn
    conn = connection.create_connection(
  File "/home/frozenwolf/miniconda3/envs/citylearn/lib/python3.10/site-packages/urllib3/util/connection.py", line 72, in create_connection
    for res in socket.getaddrinfo(host, port, family, socket.SOCK_STREAM):
  File "/home/frozenwolf/miniconda3/envs/citylearn/lib/python3.10/socket.py", line 955, in getaddrinfo
    for res in _socket.getaddrinfo(host, port, family, type, proto, flags):
socket.gaierror: [Errno -3] Temporary failure in name resolution

During handling of the above exception, another exception occurred:

Traceback (most recent call last):
  File "/home/frozenwolf/miniconda3/envs/citylearn/lib/python3.10/site-packages/urllib3/connectionpool.py", line 703, in urlopen
    httplib_response = self._make_request(
  File "/home/frozenwolf/miniconda3/envs/citylearn/lib/python3.10/site-packages/urllib3/connectionpool.py", line 386, in _make_request
    self._validate_conn(conn)
  File "/home/frozenwolf/miniconda3/envs/citylearn/lib/python3.10/site-packages/urllib3/connectionpool.py", line 1040, in _validate_conn
    conn.connect()
  File "/home/frozenwolf/miniconda3/envs/citylearn/lib/python3.10/site-packages/urllib3/connection.py", line 358, in connect
    self.sock = conn = self._new_conn()
  File "/home/frozenwolf/miniconda3/envs/citylearn/lib/python3.10/site-packages/urllib3/connection.py", line 186, in _new_conn
    raise NewConnectionError(
urllib3.exceptions.NewConnectionError: <urllib3.connection.HTTPSConnection object at 0x7fc3a9213e50>: Failed to establish a new connection: [Errno -3] Temporary failure in name resolution

During handling of the above exception, another exception occurred:

Traceback (most recent call last):
  File "/home/frozenwolf/miniconda3/envs/citylearn/lib/python3.10/site-packages/requests/adapters.py", line 440, in send
    resp = conn.urlopen(
  File "/home/frozenwolf/miniconda3/envs/citylearn/lib/python3.10/site-packages/urllib3/connectionpool.py", line 785, in urlopen
    retries = retries.increment(
  File "/home/frozenwolf/miniconda3/envs/citylearn/lib/python3.10/site-packages/urllib3/util/retry.py", line 592, in increment
    raise MaxRetryError(_pool, url, error or ResponseError(cause))
urllib3.exceptions.MaxRetryError: HTTPSConnectionPool(host='api.wandb.ai', port=443): Max retries exceeded with url: /graphql (Caused by NewConnectionError('<urllib3.connection.HTTPSConnection object at 0x7fc3a9213e50>: Failed to establish a new connection: [Errno -3] Temporary failure in name resolution'))

During handling of the above exception, another exception occurred:

Traceback (most recent call last):
  File "/home/frozenwolf/miniconda3/envs/citylearn/lib/python3.10/site-packages/wandb/sdk/lib/retry.py", line 113, in __call__
    result = self._call_fn(*args, **kwargs)
  File "/home/frozenwolf/miniconda3/envs/citylearn/lib/python3.10/site-packages/wandb/sdk/internal/internal_api.py", line 204, in execute
    return self.client.execute(*args, **kwargs)  # type: ignore
  File "/home/frozenwolf/miniconda3/envs/citylearn/lib/python3.10/site-packages/wandb/vendor/gql-0.2.0/wandb_gql/client.py", line 52, in execute
    result = self._get_result(document, *args, **kwargs)
  File "/home/frozenwolf/miniconda3/envs/citylearn/lib/python3.10/site-packages/wandb/vendor/gql-0.2.0/wandb_gql/client.py", line 60, in _get_result
    return self.transport.execute(document, *args, **kwargs)
  File "/home/frozenwolf/miniconda3/envs/citylearn/lib/python3.10/site-packages/wandb/vendor/gql-0.2.0/wandb_gql/transport/requests.py", line 38, in execute
    request = requests.post(self.url, **post_args)
  File "/home/frozenwolf/miniconda3/envs/citylearn/lib/python3.10/site-packages/requests/api.py", line 117, in post
    return request('post', url, data=data, json=json, **kwargs)
  File "/home/frozenwolf/miniconda3/envs/citylearn/lib/python3.10/site-packages/requests/api.py", line 61, in request
    return session.request(method=method, url=url, **kwargs)
  File "/home/frozenwolf/miniconda3/envs/citylearn/lib/python3.10/site-packages/requests/sessions.py", line 529, in request
    resp = self.send(prep, **send_kwargs)
  File "/home/frozenwolf/miniconda3/envs/citylearn/lib/python3.10/site-packages/requests/sessions.py", line 645, in send
    r = adapter.send(request, **kwargs)
  File "/home/frozenwolf/miniconda3/envs/citylearn/lib/python3.10/site-packages/requests/adapters.py", line 519, in send
    raise ConnectionError(e, request=request)
requests.exceptions.ConnectionError: HTTPSConnectionPool(host='api.wandb.ai', port=443): Max retries exceeded with url: /graphql (Caused by NewConnectionError('<urllib3.connection.HTTPSConnection object at 0x7fc3a9213e50>: Failed to establish a new connection: [Errno -3] Temporary failure in name resolution'))
2022-09-04 21:56:10 ERROR Retry attempt failed:
Traceback (most recent call last):
  File "/home/frozenwolf/miniconda3/envs/citylearn/lib/python3.10/site-packages/urllib3/connectionpool.py", line 703, in urlopen
    httplib_response = self._make_request(
  File "/home/frozenwolf/miniconda3/envs/citylearn/lib/python3.10/site-packages/urllib3/connectionpool.py", line 449, in _make_request
    six.raise_from(e, None)
  File "<string>", line 3, in raise_from
  File "/home/frozenwolf/miniconda3/envs/citylearn/lib/python3.10/site-packages/urllib3/connectionpool.py", line 444, in _make_request
    httplib_response = conn.getresponse()
  File "/home/frozenwolf/miniconda3/envs/citylearn/lib/python3.10/http/client.py", line 1374, in getresponse
    response.begin()
  File "/home/frozenwolf/miniconda3/envs/citylearn/lib/python3.10/http/client.py", line 318, in begin
    version, status, reason = self._read_status()
  File "/home/frozenwolf/miniconda3/envs/citylearn/lib/python3.10/http/client.py", line 287, in _read_status
    raise RemoteDisconnected("Remote end closed connection without"
http.client.RemoteDisconnected: Remote end closed connection without response

During handling of the above exception, another exception occurred:

Traceback (most recent call last):
  File "/home/frozenwolf/miniconda3/envs/citylearn/lib/python3.10/site-packages/requests/adapters.py", line 440, in send
    resp = conn.urlopen(
  File "/home/frozenwolf/miniconda3/envs/citylearn/lib/python3.10/site-packages/urllib3/connectionpool.py", line 785, in urlopen
    retries = retries.increment(
  File "/home/frozenwolf/miniconda3/envs/citylearn/lib/python3.10/site-packages/urllib3/util/retry.py", line 550, in increment
    raise six.reraise(type(error), error, _stacktrace)
  File "/home/frozenwolf/miniconda3/envs/citylearn/lib/python3.10/site-packages/urllib3/packages/six.py", line 769, in reraise
    raise value.with_traceback(tb)
  File "/home/frozenwolf/miniconda3/envs/citylearn/lib/python3.10/site-packages/urllib3/connectionpool.py", line 703, in urlopen
    httplib_response = self._make_request(
  File "/home/frozenwolf/miniconda3/envs/citylearn/lib/python3.10/site-packages/urllib3/connectionpool.py", line 449, in _make_request
    six.raise_from(e, None)
  File "<string>", line 3, in raise_from
  File "/home/frozenwolf/miniconda3/envs/citylearn/lib/python3.10/site-packages/urllib3/connectionpool.py", line 444, in _make_request
    httplib_response = conn.getresponse()
  File "/home/frozenwolf/miniconda3/envs/citylearn/lib/python3.10/http/client.py", line 1374, in getresponse
    response.begin()
  File "/home/frozenwolf/miniconda3/envs/citylearn/lib/python3.10/http/client.py", line 318, in begin
    version, status, reason = self._read_status()
  File "/home/frozenwolf/miniconda3/envs/citylearn/lib/python3.10/http/client.py", line 287, in _read_status
    raise RemoteDisconnected("Remote end closed connection without"
urllib3.exceptions.ProtocolError: ('Connection aborted.', RemoteDisconnected('Remote end closed connection without response'))

During handling of the above exception, another exception occurred:

Traceback (most recent call last):
  File "/home/frozenwolf/miniconda3/envs/citylearn/lib/python3.10/site-packages/wandb/sdk/lib/retry.py", line 113, in __call__
    result = self._call_fn(*args, **kwargs)
  File "/home/frozenwolf/miniconda3/envs/citylearn/lib/python3.10/site-packages/wandb/sdk/internal/internal_api.py", line 204, in execute
    return self.client.execute(*args, **kwargs)  # type: ignore
  File "/home/frozenwolf/miniconda3/envs/citylearn/lib/python3.10/site-packages/wandb/vendor/gql-0.2.0/wandb_gql/client.py", line 52, in execute
    result = self._get_result(document, *args, **kwargs)
  File "/home/frozenwolf/miniconda3/envs/citylearn/lib/python3.10/site-packages/wandb/vendor/gql-0.2.0/wandb_gql/client.py", line 60, in _get_result
    return self.transport.execute(document, *args, **kwargs)
  File "/home/frozenwolf/miniconda3/envs/citylearn/lib/python3.10/site-packages/wandb/vendor/gql-0.2.0/wandb_gql/transport/requests.py", line 38, in execute
    request = requests.post(self.url, **post_args)
  File "/home/frozenwolf/miniconda3/envs/citylearn/lib/python3.10/site-packages/requests/api.py", line 117, in post
    return request('post', url, data=data, json=json, **kwargs)
  File "/home/frozenwolf/miniconda3/envs/citylearn/lib/python3.10/site-packages/requests/api.py", line 61, in request
    return session.request(method=method, url=url, **kwargs)
  File "/home/frozenwolf/miniconda3/envs/citylearn/lib/python3.10/site-packages/requests/sessions.py", line 529, in request
    resp = self.send(prep, **send_kwargs)
  File "/home/frozenwolf/miniconda3/envs/citylearn/lib/python3.10/site-packages/requests/sessions.py", line 645, in send
    r = adapter.send(request, **kwargs)
  File "/home/frozenwolf/miniconda3/envs/citylearn/lib/python3.10/site-packages/requests/adapters.py", line 501, in send
    raise ConnectionError(err, request=request)
requests.exceptions.ConnectionError: ('Connection aborted.', RemoteDisconnected('Remote end closed connection without response'))
2022-09-04 22:21:33 ERROR Retry attempt failed:
Traceback (most recent call last):
  File "/home/frozenwolf/miniconda3/envs/citylearn/lib/python3.10/site-packages/urllib3/connection.py", line 174, in _new_conn
    conn = connection.create_connection(
  File "/home/frozenwolf/miniconda3/envs/citylearn/lib/python3.10/site-packages/urllib3/util/connection.py", line 95, in create_connection
    raise err
  File "/home/frozenwolf/miniconda3/envs/citylearn/lib/python3.10/site-packages/urllib3/util/connection.py", line 85, in create_connection
    sock.connect(sa)
TimeoutError: timed out

During handling of the above exception, another exception occurred:

Traceback (most recent call last):
  File "/home/frozenwolf/miniconda3/envs/citylearn/lib/python3.10/site-packages/urllib3/connectionpool.py", line 703, in urlopen
    httplib_response = self._make_request(
  File "/home/frozenwolf/miniconda3/envs/citylearn/lib/python3.10/site-packages/urllib3/connectionpool.py", line 386, in _make_request
    self._validate_conn(conn)
  File "/home/frozenwolf/miniconda3/envs/citylearn/lib/python3.10/site-packages/urllib3/connectionpool.py", line 1040, in _validate_conn
    conn.connect()
  File "/home/frozenwolf/miniconda3/envs/citylearn/lib/python3.10/site-packages/urllib3/connection.py", line 358, in connect
    self.sock = conn = self._new_conn()
  File "/home/frozenwolf/miniconda3/envs/citylearn/lib/python3.10/site-packages/urllib3/connection.py", line 179, in _new_conn
    raise ConnectTimeoutError(
urllib3.exceptions.ConnectTimeoutError: (<urllib3.connection.HTTPSConnection object at 0x7fc3a9212bc0>, 'Connection to api.wandb.ai timed out. (connect timeout=60)')

During handling of the above exception, another exception occurred:

Traceback (most recent call last):
  File "/home/frozenwolf/miniconda3/envs/citylearn/lib/python3.10/site-packages/requests/adapters.py", line 440, in send
    resp = conn.urlopen(
  File "/home/frozenwolf/miniconda3/envs/citylearn/lib/python3.10/site-packages/urllib3/connectionpool.py", line 785, in urlopen
    retries = retries.increment(
  File "/home/frozenwolf/miniconda3/envs/citylearn/lib/python3.10/site-packages/urllib3/util/retry.py", line 592, in increment
    raise MaxRetryError(_pool, url, error or ResponseError(cause))
urllib3.exceptions.MaxRetryError: HTTPSConnectionPool(host='api.wandb.ai', port=443): Max retries exceeded with url: /graphql (Caused by ConnectTimeoutError(<urllib3.connection.HTTPSConnection object at 0x7fc3a9212bc0>, 'Connection to api.wandb.ai timed out. (connect timeout=60)'))

During handling of the above exception, another exception occurred:

Traceback (most recent call last):
  File "/home/frozenwolf/miniconda3/envs/citylearn/lib/python3.10/site-packages/wandb/sdk/lib/retry.py", line 113, in __call__
    result = self._call_fn(*args, **kwargs)
  File "/home/frozenwolf/miniconda3/envs/citylearn/lib/python3.10/site-packages/wandb/sdk/internal/internal_api.py", line 204, in execute
    return self.client.execute(*args, **kwargs)  # type: ignore
  File "/home/frozenwolf/miniconda3/envs/citylearn/lib/python3.10/site-packages/wandb/vendor/gql-0.2.0/wandb_gql/client.py", line 52, in execute
    result = self._get_result(document, *args, **kwargs)
  File "/home/frozenwolf/miniconda3/envs/citylearn/lib/python3.10/site-packages/wandb/vendor/gql-0.2.0/wandb_gql/client.py", line 60, in _get_result
    return self.transport.execute(document, *args, **kwargs)
  File "/home/frozenwolf/miniconda3/envs/citylearn/lib/python3.10/site-packages/wandb/vendor/gql-0.2.0/wandb_gql/transport/requests.py", line 38, in execute
    request = requests.post(self.url, **post_args)
  File "/home/frozenwolf/miniconda3/envs/citylearn/lib/python3.10/site-packages/requests/api.py", line 117, in post
    return request('post', url, data=data, json=json, **kwargs)
  File "/home/frozenwolf/miniconda3/envs/citylearn/lib/python3.10/site-packages/requests/api.py", line 61, in request
    return session.request(method=method, url=url, **kwargs)
  File "/home/frozenwolf/miniconda3/envs/citylearn/lib/python3.10/site-packages/requests/sessions.py", line 529, in request
    resp = self.send(prep, **send_kwargs)
  File "/home/frozenwolf/miniconda3/envs/citylearn/lib/python3.10/site-packages/requests/sessions.py", line 645, in send
    r = adapter.send(request, **kwargs)
  File "/home/frozenwolf/miniconda3/envs/citylearn/lib/python3.10/site-packages/requests/adapters.py", line 507, in send
    raise ConnectTimeout(e, request=request)
requests.exceptions.ConnectTimeout: HTTPSConnectionPool(host='api.wandb.ai', port=443): Max retries exceeded with url: /graphql (Caused by ConnectTimeoutError(<urllib3.connection.HTTPSConnection object at 0x7fc3a9212bc0>, 'Connection to api.wandb.ai timed out. (connect timeout=60)'))
2022-09-05 00:08:00 ERROR Retry attempt failed:
Traceback (most recent call last):
  File "/home/frozenwolf/miniconda3/envs/citylearn/lib/python3.10/site-packages/urllib3/connection.py", line 174, in _new_conn
    conn = connection.create_connection(
  File "/home/frozenwolf/miniconda3/envs/citylearn/lib/python3.10/site-packages/urllib3/util/connection.py", line 72, in create_connection
    for res in socket.getaddrinfo(host, port, family, socket.SOCK_STREAM):
  File "/home/frozenwolf/miniconda3/envs/citylearn/lib/python3.10/socket.py", line 955, in getaddrinfo
    for res in _socket.getaddrinfo(host, port, family, type, proto, flags):
socket.gaierror: [Errno -3] Temporary failure in name resolution

During handling of the above exception, another exception occurred:

Traceback (most recent call last):
  File "/home/frozenwolf/miniconda3/envs/citylearn/lib/python3.10/site-packages/urllib3/connectionpool.py", line 703, in urlopen
    httplib_response = self._make_request(
  File "/home/frozenwolf/miniconda3/envs/citylearn/lib/python3.10/site-packages/urllib3/connectionpool.py", line 386, in _make_request
    self._validate_conn(conn)
  File "/home/frozenwolf/miniconda3/envs/citylearn/lib/python3.10/site-packages/urllib3/connectionpool.py", line 1040, in _validate_conn
    conn.connect()
  File "/home/frozenwolf/miniconda3/envs/citylearn/lib/python3.10/site-packages/urllib3/connection.py", line 358, in connect
    self.sock = conn = self._new_conn()
  File "/home/frozenwolf/miniconda3/envs/citylearn/lib/python3.10/site-packages/urllib3/connection.py", line 186, in _new_conn
    raise NewConnectionError(
urllib3.exceptions.NewConnectionError: <urllib3.connection.HTTPSConnection object at 0x7fc3a9201240>: Failed to establish a new connection: [Errno -3] Temporary failure in name resolution

During handling of the above exception, another exception occurred:

Traceback (most recent call last):
  File "/home/frozenwolf/miniconda3/envs/citylearn/lib/python3.10/site-packages/requests/adapters.py", line 440, in send
    resp = conn.urlopen(
  File "/home/frozenwolf/miniconda3/envs/citylearn/lib/python3.10/site-packages/urllib3/connectionpool.py", line 785, in urlopen
    retries = retries.increment(
  File "/home/frozenwolf/miniconda3/envs/citylearn/lib/python3.10/site-packages/urllib3/util/retry.py", line 592, in increment
    raise MaxRetryError(_pool, url, error or ResponseError(cause))
urllib3.exceptions.MaxRetryError: HTTPSConnectionPool(host='api.wandb.ai', port=443): Max retries exceeded with url: /graphql (Caused by NewConnectionError('<urllib3.connection.HTTPSConnection object at 0x7fc3a9201240>: Failed to establish a new connection: [Errno -3] Temporary failure in name resolution'))

During handling of the above exception, another exception occurred:

Traceback (most recent call last):
  File "/home/frozenwolf/miniconda3/envs/citylearn/lib/python3.10/site-packages/wandb/sdk/lib/retry.py", line 113, in __call__
    result = self._call_fn(*args, **kwargs)
  File "/home/frozenwolf/miniconda3/envs/citylearn/lib/python3.10/site-packages/wandb/sdk/internal/internal_api.py", line 204, in execute
    return self.client.execute(*args, **kwargs)  # type: ignore
  File "/home/frozenwolf/miniconda3/envs/citylearn/lib/python3.10/site-packages/wandb/vendor/gql-0.2.0/wandb_gql/client.py", line 52, in execute
    result = self._get_result(document, *args, **kwargs)
  File "/home/frozenwolf/miniconda3/envs/citylearn/lib/python3.10/site-packages/wandb/vendor/gql-0.2.0/wandb_gql/client.py", line 60, in _get_result
    return self.transport.execute(document, *args, **kwargs)
  File "/home/frozenwolf/miniconda3/envs/citylearn/lib/python3.10/site-packages/wandb/vendor/gql-0.2.0/wandb_gql/transport/requests.py", line 38, in execute
    request = requests.post(self.url, **post_args)
  File "/home/frozenwolf/miniconda3/envs/citylearn/lib/python3.10/site-packages/requests/api.py", line 117, in post
    return request('post', url, data=data, json=json, **kwargs)
  File "/home/frozenwolf/miniconda3/envs/citylearn/lib/python3.10/site-packages/requests/api.py", line 61, in request
    return session.request(method=method, url=url, **kwargs)
  File "/home/frozenwolf/miniconda3/envs/citylearn/lib/python3.10/site-packages/requests/sessions.py", line 529, in request
    resp = self.send(prep, **send_kwargs)
  File "/home/frozenwolf/miniconda3/envs/citylearn/lib/python3.10/site-packages/requests/sessions.py", line 645, in send
    r = adapter.send(request, **kwargs)
  File "/home/frozenwolf/miniconda3/envs/citylearn/lib/python3.10/site-packages/requests/adapters.py", line 519, in send
    raise ConnectionError(e, request=request)
requests.exceptions.ConnectionError: HTTPSConnectionPool(host='api.wandb.ai', port=443): Max retries exceeded with url: /graphql (Caused by NewConnectionError('<urllib3.connection.HTTPSConnection object at 0x7fc3a9201240>: Failed to establish a new connection: [Errno -3] Temporary failure in name resolution'))
2022-09-05 01:29:31 ERROR Retry attempt failed:
Traceback (most recent call last):
  File "/home/frozenwolf/miniconda3/envs/citylearn/lib/python3.10/site-packages/urllib3/connectionpool.py", line 703, in urlopen
    httplib_response = self._make_request(
  File "/home/frozenwolf/miniconda3/envs/citylearn/lib/python3.10/site-packages/urllib3/connectionpool.py", line 386, in _make_request
    self._validate_conn(conn)
  File "/home/frozenwolf/miniconda3/envs/citylearn/lib/python3.10/site-packages/urllib3/connectionpool.py", line 1040, in _validate_conn
    conn.connect()
  File "/home/frozenwolf/miniconda3/envs/citylearn/lib/python3.10/site-packages/urllib3/connection.py", line 414, in connect
    self.sock = ssl_wrap_socket(
  File "/home/frozenwolf/miniconda3/envs/citylearn/lib/python3.10/site-packages/urllib3/util/ssl_.py", line 449, in ssl_wrap_socket
    ssl_sock = _ssl_wrap_socket_impl(
  File "/home/frozenwolf/miniconda3/envs/citylearn/lib/python3.10/site-packages/urllib3/util/ssl_.py", line 493, in _ssl_wrap_socket_impl
    return ssl_context.wrap_socket(sock, server_hostname=server_hostname)
  File "/home/frozenwolf/miniconda3/envs/citylearn/lib/python3.10/ssl.py", line 512, in wrap_socket
    return self.sslsocket_class._create(
  File "/home/frozenwolf/miniconda3/envs/citylearn/lib/python3.10/ssl.py", line 1070, in _create
    self.do_handshake()
  File "/home/frozenwolf/miniconda3/envs/citylearn/lib/python3.10/ssl.py", line 1341, in do_handshake
    self._sslobj.do_handshake()
ssl.SSLEOFError: EOF occurred in violation of protocol (_ssl.c:997)

During handling of the above exception, another exception occurred:

Traceback (most recent call last):
  File "/home/frozenwolf/miniconda3/envs/citylearn/lib/python3.10/site-packages/requests/adapters.py", line 440, in send
    resp = conn.urlopen(
  File "/home/frozenwolf/miniconda3/envs/citylearn/lib/python3.10/site-packages/urllib3/connectionpool.py", line 785, in urlopen
    retries = retries.increment(
  File "/home/frozenwolf/miniconda3/envs/citylearn/lib/python3.10/site-packages/urllib3/util/retry.py", line 592, in increment
    raise MaxRetryError(_pool, url, error or ResponseError(cause))
urllib3.exceptions.MaxRetryError: HTTPSConnectionPool(host='api.wandb.ai', port=443): Max retries exceeded with url: /graphql (Caused by SSLError(SSLEOFError(8, 'EOF occurred in violation of protocol (_ssl.c:997)')))

During handling of the above exception, another exception occurred:

Traceback (most recent call last):
  File "/home/frozenwolf/miniconda3/envs/citylearn/lib/python3.10/site-packages/wandb/sdk/lib/retry.py", line 113, in __call__
    result = self._call_fn(*args, **kwargs)
  File "/home/frozenwolf/miniconda3/envs/citylearn/lib/python3.10/site-packages/wandb/sdk/internal/internal_api.py", line 204, in execute
    return self.client.execute(*args, **kwargs)  # type: ignore
  File "/home/frozenwolf/miniconda3/envs/citylearn/lib/python3.10/site-packages/wandb/vendor/gql-0.2.0/wandb_gql/client.py", line 52, in execute
    result = self._get_result(document, *args, **kwargs)
  File "/home/frozenwolf/miniconda3/envs/citylearn/lib/python3.10/site-packages/wandb/vendor/gql-0.2.0/wandb_gql/client.py", line 60, in _get_result
    return self.transport.execute(document, *args, **kwargs)
  File "/home/frozenwolf/miniconda3/envs/citylearn/lib/python3.10/site-packages/wandb/vendor/gql-0.2.0/wandb_gql/transport/requests.py", line 38, in execute
    request = requests.post(self.url, **post_args)
  File "/home/frozenwolf/miniconda3/envs/citylearn/lib/python3.10/site-packages/requests/api.py", line 117, in post
    return request('post', url, data=data, json=json, **kwargs)
  File "/home/frozenwolf/miniconda3/envs/citylearn/lib/python3.10/site-packages/requests/api.py", line 61, in request
    return session.request(method=method, url=url, **kwargs)
  File "/home/frozenwolf/miniconda3/envs/citylearn/lib/python3.10/site-packages/requests/sessions.py", line 529, in request
    resp = self.send(prep, **send_kwargs)
  File "/home/frozenwolf/miniconda3/envs/citylearn/lib/python3.10/site-packages/requests/sessions.py", line 645, in send
    r = adapter.send(request, **kwargs)
  File "/home/frozenwolf/miniconda3/envs/citylearn/lib/python3.10/site-packages/requests/adapters.py", line 517, in send
    raise SSLError(e, request=request)
requests.exceptions.SSLError: HTTPSConnectionPool(host='api.wandb.ai', port=443): Max retries exceeded with url: /graphql (Caused by SSLError(SSLEOFError(8, 'EOF occurred in violation of protocol (_ssl.c:997)')))
2022-09-05 01:49:13 ERROR Retry attempt failed:
Traceback (most recent call last):
  File "/home/frozenwolf/miniconda3/envs/citylearn/lib/python3.10/site-packages/urllib3/connectionpool.py", line 703, in urlopen
    httplib_response = self._make_request(
  File "/home/frozenwolf/miniconda3/envs/citylearn/lib/python3.10/site-packages/urllib3/connectionpool.py", line 386, in _make_request
    self._validate_conn(conn)
  File "/home/frozenwolf/miniconda3/envs/citylearn/lib/python3.10/site-packages/urllib3/connectionpool.py", line 1040, in _validate_conn
    conn.connect()
  File "/home/frozenwolf/miniconda3/envs/citylearn/lib/python3.10/site-packages/urllib3/connection.py", line 414, in connect
    self.sock = ssl_wrap_socket(
  File "/home/frozenwolf/miniconda3/envs/citylearn/lib/python3.10/site-packages/urllib3/util/ssl_.py", line 449, in ssl_wrap_socket
    ssl_sock = _ssl_wrap_socket_impl(
  File "/home/frozenwolf/miniconda3/envs/citylearn/lib/python3.10/site-packages/urllib3/util/ssl_.py", line 493, in _ssl_wrap_socket_impl
    return ssl_context.wrap_socket(sock, server_hostname=server_hostname)
  File "/home/frozenwolf/miniconda3/envs/citylearn/lib/python3.10/ssl.py", line 512, in wrap_socket
    return self.sslsocket_class._create(
  File "/home/frozenwolf/miniconda3/envs/citylearn/lib/python3.10/ssl.py", line 1070, in _create
    self.do_handshake()
  File "/home/frozenwolf/miniconda3/envs/citylearn/lib/python3.10/ssl.py", line 1341, in do_handshake
    self._sslobj.do_handshake()
ssl.SSLEOFError: EOF occurred in violation of protocol (_ssl.c:997)

During handling of the above exception, another exception occurred:

Traceback (most recent call last):
  File "/home/frozenwolf/miniconda3/envs/citylearn/lib/python3.10/site-packages/requests/adapters.py", line 440, in send
    resp = conn.urlopen(
  File "/home/frozenwolf/miniconda3/envs/citylearn/lib/python3.10/site-packages/urllib3/connectionpool.py", line 785, in urlopen
    retries = retries.increment(
  File "/home/frozenwolf/miniconda3/envs/citylearn/lib/python3.10/site-packages/urllib3/util/retry.py", line 592, in increment
    raise MaxRetryError(_pool, url, error or ResponseError(cause))
urllib3.exceptions.MaxRetryError: HTTPSConnectionPool(host='api.wandb.ai', port=443): Max retries exceeded with url: /graphql (Caused by SSLError(SSLEOFError(8, 'EOF occurred in violation of protocol (_ssl.c:997)')))

During handling of the above exception, another exception occurred:

Traceback (most recent call last):
  File "/home/frozenwolf/miniconda3/envs/citylearn/lib/python3.10/site-packages/wandb/sdk/lib/retry.py", line 113, in __call__
    result = self._call_fn(*args, **kwargs)
  File "/home/frozenwolf/miniconda3/envs/citylearn/lib/python3.10/site-packages/wandb/sdk/internal/internal_api.py", line 204, in execute
    return self.client.execute(*args, **kwargs)  # type: ignore
  File "/home/frozenwolf/miniconda3/envs/citylearn/lib/python3.10/site-packages/wandb/vendor/gql-0.2.0/wandb_gql/client.py", line 52, in execute
    result = self._get_result(document, *args, **kwargs)
  File "/home/frozenwolf/miniconda3/envs/citylearn/lib/python3.10/site-packages/wandb/vendor/gql-0.2.0/wandb_gql/client.py", line 60, in _get_result
    return self.transport.execute(document, *args, **kwargs)
  File "/home/frozenwolf/miniconda3/envs/citylearn/lib/python3.10/site-packages/wandb/vendor/gql-0.2.0/wandb_gql/transport/requests.py", line 38, in execute
    request = requests.post(self.url, **post_args)
  File "/home/frozenwolf/miniconda3/envs/citylearn/lib/python3.10/site-packages/requests/api.py", line 117, in post
    return request('post', url, data=data, json=json, **kwargs)
  File "/home/frozenwolf/miniconda3/envs/citylearn/lib/python3.10/site-packages/requests/api.py", line 61, in request
    return session.request(method=method, url=url, **kwargs)
  File "/home/frozenwolf/miniconda3/envs/citylearn/lib/python3.10/site-packages/requests/sessions.py", line 529, in request
    resp = self.send(prep, **send_kwargs)
  File "/home/frozenwolf/miniconda3/envs/citylearn/lib/python3.10/site-packages/requests/sessions.py", line 645, in send
    r = adapter.send(request, **kwargs)
  File "/home/frozenwolf/miniconda3/envs/citylearn/lib/python3.10/site-packages/requests/adapters.py", line 517, in send
    raise SSLError(e, request=request)
requests.exceptions.SSLError: HTTPSConnectionPool(host='api.wandb.ai', port=443): Max retries exceeded with url: /graphql (Caused by SSLError(SSLEOFError(8, 'EOF occurred in violation of protocol (_ssl.c:997)')))
2022-09-05 01:56:27 ERROR Retry attempt failed:
Traceback (most recent call last):
  File "/home/frozenwolf/miniconda3/envs/citylearn/lib/python3.10/site-packages/urllib3/connectionpool.py", line 703, in urlopen
    httplib_response = self._make_request(
  File "/home/frozenwolf/miniconda3/envs/citylearn/lib/python3.10/site-packages/urllib3/connectionpool.py", line 386, in _make_request
    self._validate_conn(conn)
  File "/home/frozenwolf/miniconda3/envs/citylearn/lib/python3.10/site-packages/urllib3/connectionpool.py", line 1040, in _validate_conn
    conn.connect()
  File "/home/frozenwolf/miniconda3/envs/citylearn/lib/python3.10/site-packages/urllib3/connection.py", line 414, in connect
    self.sock = ssl_wrap_socket(
  File "/home/frozenwolf/miniconda3/envs/citylearn/lib/python3.10/site-packages/urllib3/util/ssl_.py", line 449, in ssl_wrap_socket
    ssl_sock = _ssl_wrap_socket_impl(
  File "/home/frozenwolf/miniconda3/envs/citylearn/lib/python3.10/site-packages/urllib3/util/ssl_.py", line 493, in _ssl_wrap_socket_impl
    return ssl_context.wrap_socket(sock, server_hostname=server_hostname)
  File "/home/frozenwolf/miniconda3/envs/citylearn/lib/python3.10/ssl.py", line 512, in wrap_socket
    return self.sslsocket_class._create(
  File "/home/frozenwolf/miniconda3/envs/citylearn/lib/python3.10/ssl.py", line 1070, in _create
    self.do_handshake()
  File "/home/frozenwolf/miniconda3/envs/citylearn/lib/python3.10/ssl.py", line 1341, in do_handshake
    self._sslobj.do_handshake()
ssl.SSLEOFError: EOF occurred in violation of protocol (_ssl.c:997)

During handling of the above exception, another exception occurred:

Traceback (most recent call last):
  File "/home/frozenwolf/miniconda3/envs/citylearn/lib/python3.10/site-packages/requests/adapters.py", line 440, in send
    resp = conn.urlopen(
  File "/home/frozenwolf/miniconda3/envs/citylearn/lib/python3.10/site-packages/urllib3/connectionpool.py", line 785, in urlopen
    retries = retries.increment(
  File "/home/frozenwolf/miniconda3/envs/citylearn/lib/python3.10/site-packages/urllib3/util/retry.py", line 592, in increment
    raise MaxRetryError(_pool, url, error or ResponseError(cause))
urllib3.exceptions.MaxRetryError: HTTPSConnectionPool(host='api.wandb.ai', port=443): Max retries exceeded with url: /graphql (Caused by SSLError(SSLEOFError(8, 'EOF occurred in violation of protocol (_ssl.c:997)')))

During handling of the above exception, another exception occurred:

Traceback (most recent call last):
  File "/home/frozenwolf/miniconda3/envs/citylearn/lib/python3.10/site-packages/wandb/sdk/lib/retry.py", line 113, in __call__
    result = self._call_fn(*args, **kwargs)
  File "/home/frozenwolf/miniconda3/envs/citylearn/lib/python3.10/site-packages/wandb/sdk/internal/internal_api.py", line 204, in execute
    return self.client.execute(*args, **kwargs)  # type: ignore
  File "/home/frozenwolf/miniconda3/envs/citylearn/lib/python3.10/site-packages/wandb/vendor/gql-0.2.0/wandb_gql/client.py", line 52, in execute
    result = self._get_result(document, *args, **kwargs)
  File "/home/frozenwolf/miniconda3/envs/citylearn/lib/python3.10/site-packages/wandb/vendor/gql-0.2.0/wandb_gql/client.py", line 60, in _get_result
    return self.transport.execute(document, *args, **kwargs)
  File "/home/frozenwolf/miniconda3/envs/citylearn/lib/python3.10/site-packages/wandb/vendor/gql-0.2.0/wandb_gql/transport/requests.py", line 38, in execute
    request = requests.post(self.url, **post_args)
  File "/home/frozenwolf/miniconda3/envs/citylearn/lib/python3.10/site-packages/requests/api.py", line 117, in post
    return request('post', url, data=data, json=json, **kwargs)
  File "/home/frozenwolf/miniconda3/envs/citylearn/lib/python3.10/site-packages/requests/api.py", line 61, in request
    return session.request(method=method, url=url, **kwargs)
  File "/home/frozenwolf/miniconda3/envs/citylearn/lib/python3.10/site-packages/requests/sessions.py", line 529, in request
    resp = self.send(prep, **send_kwargs)
  File "/home/frozenwolf/miniconda3/envs/citylearn/lib/python3.10/site-packages/requests/sessions.py", line 645, in send
    r = adapter.send(request, **kwargs)
  File "/home/frozenwolf/miniconda3/envs/citylearn/lib/python3.10/site-packages/requests/adapters.py", line 517, in send
    raise SSLError(e, request=request)
requests.exceptions.SSLError: HTTPSConnectionPool(host='api.wandb.ai', port=443): Max retries exceeded with url: /graphql (Caused by SSLError(SSLEOFError(8, 'EOF occurred in violation of protocol (_ssl.c:997)')))
2022-09-05 02:02:44 INFO Cleaning up finished run: ldf7sb3p
2022-09-05 02:02:45 INFO Agent received command: run
2022-09-05 02:02:45 INFO Agent starting run with config:
	actor_lr: 0.0001
	algo: ddpg
	batch_size: 256
	critic_lr: 0.0003
	device: cuda
	epochs: 1000
	gamma: 0.99
	tau: 0.03
2022-09-05 02:02:45 INFO About to run command: /usr/bin/env python citylearn-2022-starter-kit/train.py --actor_lr=0.0001 --algo=ddpg --batch_size=256 --critic_lr=0.0003 --device=cuda --epochs=1000 --gamma=0.99 --tau=0.03
2022-09-05 02:02:50 INFO Running runs: ['ov2y8ie8']
2022-09-05 08:26:57 INFO Cleaning up finished run: ov2y8ie8
2022-09-05 08:26:57 INFO Agent received command: run
2022-09-05 08:26:57 INFO Agent starting run with config:
	actor_lr: 0.0001
	algo: ddpg
	batch_size: 256
	critic_lr: 0.0003
	device: cuda
	epochs: 1000
	gamma: 0.99
	tau: 0.04
2022-09-05 08:26:58 INFO About to run command: /usr/bin/env python citylearn-2022-starter-kit/train.py --actor_lr=0.0001 --algo=ddpg --batch_size=256 --critic_lr=0.0003 --device=cuda --epochs=1000 --gamma=0.99 --tau=0.04
2022-09-05 08:27:03 INFO Running runs: ['1t9o4nz4']
2022-09-05 13:08:11 ERROR 502 response executing GraphQL.
2022-09-05 13:08:11 ERROR 
<html><head>
<meta http-equiv="content-type" content="text/html;charset=utf-8">
<title>502 Server Error</title>
</head>
<body text=#000000 bgcolor=#ffffff>
<h1>Error: Server Error</h1>
<h2>The server encountered a temporary error and could not complete your request.<p>Please try again in 30 seconds.</h2>
<h2></h2>
</body></html>

2022-09-05 15:20:36 INFO Cleaning up finished run: 1t9o4nz4
2022-09-05 15:20:37 INFO Agent received command: run
2022-09-05 15:20:37 INFO Agent starting run with config:
	actor_lr: 0.0001
	algo: ddpg
	batch_size: 256
	critic_lr: 0.0003
	device: cuda
	epochs: 1000
	gamma: 0.99
	tau: 0.05
2022-09-05 15:20:37 INFO About to run command: /usr/bin/env python citylearn-2022-starter-kit/train.py --actor_lr=0.0001 --algo=ddpg --batch_size=256 --critic_lr=0.0003 --device=cuda --epochs=1000 --gamma=0.99 --tau=0.05
2022-09-05 15:20:42 INFO Running runs: ['an2d65jb']
2022-09-05 16:58:30 ERROR Retry attempt failed:
Traceback (most recent call last):
  File "/home/frozenwolf/miniconda3/envs/citylearn/lib/python3.10/site-packages/urllib3/connection.py", line 174, in _new_conn
    conn = connection.create_connection(
  File "/home/frozenwolf/miniconda3/envs/citylearn/lib/python3.10/site-packages/urllib3/util/connection.py", line 72, in create_connection
    for res in socket.getaddrinfo(host, port, family, socket.SOCK_STREAM):
  File "/home/frozenwolf/miniconda3/envs/citylearn/lib/python3.10/socket.py", line 955, in getaddrinfo
    for res in _socket.getaddrinfo(host, port, family, type, proto, flags):
socket.gaierror: [Errno -3] Temporary failure in name resolution

During handling of the above exception, another exception occurred:

Traceback (most recent call last):
  File "/home/frozenwolf/miniconda3/envs/citylearn/lib/python3.10/site-packages/urllib3/connectionpool.py", line 703, in urlopen
    httplib_response = self._make_request(
  File "/home/frozenwolf/miniconda3/envs/citylearn/lib/python3.10/site-packages/urllib3/connectionpool.py", line 386, in _make_request
    self._validate_conn(conn)
  File "/home/frozenwolf/miniconda3/envs/citylearn/lib/python3.10/site-packages/urllib3/connectionpool.py", line 1040, in _validate_conn
    conn.connect()
  File "/home/frozenwolf/miniconda3/envs/citylearn/lib/python3.10/site-packages/urllib3/connection.py", line 358, in connect
    self.sock = conn = self._new_conn()
  File "/home/frozenwolf/miniconda3/envs/citylearn/lib/python3.10/site-packages/urllib3/connection.py", line 186, in _new_conn
    raise NewConnectionError(
urllib3.exceptions.NewConnectionError: <urllib3.connection.HTTPSConnection object at 0x7fc3a9201cc0>: Failed to establish a new connection: [Errno -3] Temporary failure in name resolution

During handling of the above exception, another exception occurred:

Traceback (most recent call last):
  File "/home/frozenwolf/miniconda3/envs/citylearn/lib/python3.10/site-packages/requests/adapters.py", line 440, in send
    resp = conn.urlopen(
  File "/home/frozenwolf/miniconda3/envs/citylearn/lib/python3.10/site-packages/urllib3/connectionpool.py", line 785, in urlopen
    retries = retries.increment(
  File "/home/frozenwolf/miniconda3/envs/citylearn/lib/python3.10/site-packages/urllib3/util/retry.py", line 592, in increment
    raise MaxRetryError(_pool, url, error or ResponseError(cause))
urllib3.exceptions.MaxRetryError: HTTPSConnectionPool(host='api.wandb.ai', port=443): Max retries exceeded with url: /graphql (Caused by NewConnectionError('<urllib3.connection.HTTPSConnection object at 0x7fc3a9201cc0>: Failed to establish a new connection: [Errno -3] Temporary failure in name resolution'))

During handling of the above exception, another exception occurred:

Traceback (most recent call last):
  File "/home/frozenwolf/miniconda3/envs/citylearn/lib/python3.10/site-packages/wandb/sdk/lib/retry.py", line 113, in __call__
    result = self._call_fn(*args, **kwargs)
  File "/home/frozenwolf/miniconda3/envs/citylearn/lib/python3.10/site-packages/wandb/sdk/internal/internal_api.py", line 204, in execute
    return self.client.execute(*args, **kwargs)  # type: ignore
  File "/home/frozenwolf/miniconda3/envs/citylearn/lib/python3.10/site-packages/wandb/vendor/gql-0.2.0/wandb_gql/client.py", line 52, in execute
    result = self._get_result(document, *args, **kwargs)
  File "/home/frozenwolf/miniconda3/envs/citylearn/lib/python3.10/site-packages/wandb/vendor/gql-0.2.0/wandb_gql/client.py", line 60, in _get_result
    return self.transport.execute(document, *args, **kwargs)
  File "/home/frozenwolf/miniconda3/envs/citylearn/lib/python3.10/site-packages/wandb/vendor/gql-0.2.0/wandb_gql/transport/requests.py", line 38, in execute
    request = requests.post(self.url, **post_args)
  File "/home/frozenwolf/miniconda3/envs/citylearn/lib/python3.10/site-packages/requests/api.py", line 117, in post
    return request('post', url, data=data, json=json, **kwargs)
  File "/home/frozenwolf/miniconda3/envs/citylearn/lib/python3.10/site-packages/requests/api.py", line 61, in request
    return session.request(method=method, url=url, **kwargs)
  File "/home/frozenwolf/miniconda3/envs/citylearn/lib/python3.10/site-packages/requests/sessions.py", line 529, in request
    resp = self.send(prep, **send_kwargs)
  File "/home/frozenwolf/miniconda3/envs/citylearn/lib/python3.10/site-packages/requests/sessions.py", line 645, in send
    r = adapter.send(request, **kwargs)
  File "/home/frozenwolf/miniconda3/envs/citylearn/lib/python3.10/site-packages/requests/adapters.py", line 519, in send
    raise ConnectionError(e, request=request)
requests.exceptions.ConnectionError: HTTPSConnectionPool(host='api.wandb.ai', port=443): Max retries exceeded with url: /graphql (Caused by NewConnectionError('<urllib3.connection.HTTPSConnection object at 0x7fc3a9201cc0>: Failed to establish a new connection: [Errno -3] Temporary failure in name resolution'))
2022-09-05 17:12:51 ERROR Retry attempt failed:
Traceback (most recent call last):
  File "/home/frozenwolf/miniconda3/envs/citylearn/lib/python3.10/site-packages/urllib3/connection.py", line 174, in _new_conn
    conn = connection.create_connection(
  File "/home/frozenwolf/miniconda3/envs/citylearn/lib/python3.10/site-packages/urllib3/util/connection.py", line 72, in create_connection
    for res in socket.getaddrinfo(host, port, family, socket.SOCK_STREAM):
  File "/home/frozenwolf/miniconda3/envs/citylearn/lib/python3.10/socket.py", line 955, in getaddrinfo
    for res in _socket.getaddrinfo(host, port, family, type, proto, flags):
socket.gaierror: [Errno -3] Temporary failure in name resolution

During handling of the above exception, another exception occurred:

Traceback (most recent call last):
  File "/home/frozenwolf/miniconda3/envs/citylearn/lib/python3.10/site-packages/urllib3/connectionpool.py", line 703, in urlopen
    httplib_response = self._make_request(
  File "/home/frozenwolf/miniconda3/envs/citylearn/lib/python3.10/site-packages/urllib3/connectionpool.py", line 386, in _make_request
    self._validate_conn(conn)
  File "/home/frozenwolf/miniconda3/envs/citylearn/lib/python3.10/site-packages/urllib3/connectionpool.py", line 1040, in _validate_conn
    conn.connect()
  File "/home/frozenwolf/miniconda3/envs/citylearn/lib/python3.10/site-packages/urllib3/connection.py", line 358, in connect
    self.sock = conn = self._new_conn()
  File "/home/frozenwolf/miniconda3/envs/citylearn/lib/python3.10/site-packages/urllib3/connection.py", line 186, in _new_conn
    raise NewConnectionError(
urllib3.exceptions.NewConnectionError: <urllib3.connection.HTTPSConnection object at 0x7fc3a9200280>: Failed to establish a new connection: [Errno -3] Temporary failure in name resolution

During handling of the above exception, another exception occurred:

Traceback (most recent call last):
  File "/home/frozenwolf/miniconda3/envs/citylearn/lib/python3.10/site-packages/requests/adapters.py", line 440, in send
    resp = conn.urlopen(
  File "/home/frozenwolf/miniconda3/envs/citylearn/lib/python3.10/site-packages/urllib3/connectionpool.py", line 785, in urlopen
    retries = retries.increment(
  File "/home/frozenwolf/miniconda3/envs/citylearn/lib/python3.10/site-packages/urllib3/util/retry.py", line 592, in increment
    raise MaxRetryError(_pool, url, error or ResponseError(cause))
urllib3.exceptions.MaxRetryError: HTTPSConnectionPool(host='api.wandb.ai', port=443): Max retries exceeded with url: /graphql (Caused by NewConnectionError('<urllib3.connection.HTTPSConnection object at 0x7fc3a9200280>: Failed to establish a new connection: [Errno -3] Temporary failure in name resolution'))

During handling of the above exception, another exception occurred:

Traceback (most recent call last):
  File "/home/frozenwolf/miniconda3/envs/citylearn/lib/python3.10/site-packages/wandb/sdk/lib/retry.py", line 113, in __call__
    result = self._call_fn(*args, **kwargs)
  File "/home/frozenwolf/miniconda3/envs/citylearn/lib/python3.10/site-packages/wandb/sdk/internal/internal_api.py", line 204, in execute
    return self.client.execute(*args, **kwargs)  # type: ignore
  File "/home/frozenwolf/miniconda3/envs/citylearn/lib/python3.10/site-packages/wandb/vendor/gql-0.2.0/wandb_gql/client.py", line 52, in execute
    result = self._get_result(document, *args, **kwargs)
  File "/home/frozenwolf/miniconda3/envs/citylearn/lib/python3.10/site-packages/wandb/vendor/gql-0.2.0/wandb_gql/client.py", line 60, in _get_result
    return self.transport.execute(document, *args, **kwargs)
  File "/home/frozenwolf/miniconda3/envs/citylearn/lib/python3.10/site-packages/wandb/vendor/gql-0.2.0/wandb_gql/transport/requests.py", line 38, in execute
    request = requests.post(self.url, **post_args)
  File "/home/frozenwolf/miniconda3/envs/citylearn/lib/python3.10/site-packages/requests/api.py", line 117, in post
    return request('post', url, data=data, json=json, **kwargs)
  File "/home/frozenwolf/miniconda3/envs/citylearn/lib/python3.10/site-packages/requests/api.py", line 61, in request
    return session.request(method=method, url=url, **kwargs)
  File "/home/frozenwolf/miniconda3/envs/citylearn/lib/python3.10/site-packages/requests/sessions.py", line 529, in request
    resp = self.send(prep, **send_kwargs)
  File "/home/frozenwolf/miniconda3/envs/citylearn/lib/python3.10/site-packages/requests/sessions.py", line 645, in send
    r = adapter.send(request, **kwargs)
  File "/home/frozenwolf/miniconda3/envs/citylearn/lib/python3.10/site-packages/requests/adapters.py", line 519, in send
    raise ConnectionError(e, request=request)
requests.exceptions.ConnectionError: HTTPSConnectionPool(host='api.wandb.ai', port=443): Max retries exceeded with url: /graphql (Caused by NewConnectionError('<urllib3.connection.HTTPSConnection object at 0x7fc3a9200280>: Failed to establish a new connection: [Errno -3] Temporary failure in name resolution'))
2022-09-05 17:28:35 ERROR Retry attempt failed:
Traceback (most recent call last):
  File "/home/frozenwolf/miniconda3/envs/citylearn/lib/python3.10/site-packages/urllib3/connection.py", line 174, in _new_conn
    conn = connection.create_connection(
  File "/home/frozenwolf/miniconda3/envs/citylearn/lib/python3.10/site-packages/urllib3/util/connection.py", line 72, in create_connection
    for res in socket.getaddrinfo(host, port, family, socket.SOCK_STREAM):
  File "/home/frozenwolf/miniconda3/envs/citylearn/lib/python3.10/socket.py", line 955, in getaddrinfo
    for res in _socket.getaddrinfo(host, port, family, type, proto, flags):
socket.gaierror: [Errno -3] Temporary failure in name resolution

During handling of the above exception, another exception occurred:

Traceback (most recent call last):
  File "/home/frozenwolf/miniconda3/envs/citylearn/lib/python3.10/site-packages/urllib3/connectionpool.py", line 703, in urlopen
    httplib_response = self._make_request(
  File "/home/frozenwolf/miniconda3/envs/citylearn/lib/python3.10/site-packages/urllib3/connectionpool.py", line 386, in _make_request
    self._validate_conn(conn)
  File "/home/frozenwolf/miniconda3/envs/citylearn/lib/python3.10/site-packages/urllib3/connectionpool.py", line 1040, in _validate_conn
    conn.connect()
  File "/home/frozenwolf/miniconda3/envs/citylearn/lib/python3.10/site-packages/urllib3/connection.py", line 358, in connect
    self.sock = conn = self._new_conn()
  File "/home/frozenwolf/miniconda3/envs/citylearn/lib/python3.10/site-packages/urllib3/connection.py", line 186, in _new_conn
    raise NewConnectionError(
urllib3.exceptions.NewConnectionError: <urllib3.connection.HTTPSConnection object at 0x7fc3a9201e10>: Failed to establish a new connection: [Errno -3] Temporary failure in name resolution

During handling of the above exception, another exception occurred:

Traceback (most recent call last):
  File "/home/frozenwolf/miniconda3/envs/citylearn/lib/python3.10/site-packages/requests/adapters.py", line 440, in send
    resp = conn.urlopen(
  File "/home/frozenwolf/miniconda3/envs/citylearn/lib/python3.10/site-packages/urllib3/connectionpool.py", line 785, in urlopen
    retries = retries.increment(
  File "/home/frozenwolf/miniconda3/envs/citylearn/lib/python3.10/site-packages/urllib3/util/retry.py", line 592, in increment
    raise MaxRetryError(_pool, url, error or ResponseError(cause))
urllib3.exceptions.MaxRetryError: HTTPSConnectionPool(host='api.wandb.ai', port=443): Max retries exceeded with url: /graphql (Caused by NewConnectionError('<urllib3.connection.HTTPSConnection object at 0x7fc3a9201e10>: Failed to establish a new connection: [Errno -3] Temporary failure in name resolution'))

During handling of the above exception, another exception occurred:

Traceback (most recent call last):
  File "/home/frozenwolf/miniconda3/envs/citylearn/lib/python3.10/site-packages/wandb/sdk/lib/retry.py", line 113, in __call__
    result = self._call_fn(*args, **kwargs)
  File "/home/frozenwolf/miniconda3/envs/citylearn/lib/python3.10/site-packages/wandb/sdk/internal/internal_api.py", line 204, in execute
    return self.client.execute(*args, **kwargs)  # type: ignore
  File "/home/frozenwolf/miniconda3/envs/citylearn/lib/python3.10/site-packages/wandb/vendor/gql-0.2.0/wandb_gql/client.py", line 52, in execute
    result = self._get_result(document, *args, **kwargs)
  File "/home/frozenwolf/miniconda3/envs/citylearn/lib/python3.10/site-packages/wandb/vendor/gql-0.2.0/wandb_gql/client.py", line 60, in _get_result
    return self.transport.execute(document, *args, **kwargs)
  File "/home/frozenwolf/miniconda3/envs/citylearn/lib/python3.10/site-packages/wandb/vendor/gql-0.2.0/wandb_gql/transport/requests.py", line 38, in execute
    request = requests.post(self.url, **post_args)
  File "/home/frozenwolf/miniconda3/envs/citylearn/lib/python3.10/site-packages/requests/api.py", line 117, in post
    return request('post', url, data=data, json=json, **kwargs)
  File "/home/frozenwolf/miniconda3/envs/citylearn/lib/python3.10/site-packages/requests/api.py", line 61, in request
    return session.request(method=method, url=url, **kwargs)
  File "/home/frozenwolf/miniconda3/envs/citylearn/lib/python3.10/site-packages/requests/sessions.py", line 529, in request
    resp = self.send(prep, **send_kwargs)
  File "/home/frozenwolf/miniconda3/envs/citylearn/lib/python3.10/site-packages/requests/sessions.py", line 645, in send
    r = adapter.send(request, **kwargs)
  File "/home/frozenwolf/miniconda3/envs/citylearn/lib/python3.10/site-packages/requests/adapters.py", line 519, in send
    raise ConnectionError(e, request=request)
requests.exceptions.ConnectionError: HTTPSConnectionPool(host='api.wandb.ai', port=443): Max retries exceeded with url: /graphql (Caused by NewConnectionError('<urllib3.connection.HTTPSConnection object at 0x7fc3a9201e10>: Failed to establish a new connection: [Errno -3] Temporary failure in name resolution'))
